Workbook
Name OLE_LINK1: 'Excercise - Al '!$P$59
Name OLE_LINK1: 'MSEL INFO ONLY'!$P$149

Sheet Excercise - Al 
A1: MSEL NUMBER | B1: DATE | C1: Time | D1: STATUS | E1: INJECT DTG | F1: SUBJECT | G1: INJECT MODE | H1: SEND FROM (Simulated) | I1: INJECTED BY | J1: SEND TO | K1: STORYLINE/THREAD | L1: ESF | M1: DESCRIPTION | N1: EXPECTED ACTION | O1: NOTES/REMARKS | P1: IMPLEMENTER (Actual Narrative) | Q1: BACKGROUND INFORMATION | R1: Inject Author
A2: 1 | D2: Omitted | E2: 40298.208 | F2: 31st CHEM BDE - Notifies select staff | G2: Not Injected | R2: Napier
A3: 2 | B3: 40299 | C3: 40299.167 | D3: Injected | E3: 40299.167 | F3: INFO | G3: Email | H3: Simcell - National Hurricane Center | I3: KEANE | J3: JOC, All | K3: Tropical Depression One Forms | L3: 5, 15 | M3: Tropical Depression One Forms | P3: On 01 May, 0400 HRS CDT, The National Hurricane Center issues Tropical Depression Advisory "One". Current Location 14.5 N 74.1 W Max Sustained Wind 30mph | R3: Keane
A4: 3 | D4: Omitted | E4: 40299.208 | F4: 31st CHEM BDE - Telecon with unit CDRs and issue verbal WARNO | G4: Not Injected | R4: Napier
A5: 4 | D5: Omitted | E5: 40299.208 | F5: 31st CHEM BDE - Test alert roster of key personnel and for the 1165th and 690th | G5: Not Injected | R5: Napier
A6: 5 | B6: 40299 | C6: 40299.417 | D6: Injected | E6: 40299.417 | F6: INFO | G6: Email | H6: Simcell - National Hurricane Center | I6: KEANE | J6: JOC, All | K6: Tropical Storm Al Update 2 | L6: 5, 15 | M6: Tropical Storm Al Update 2 | P6: ...FIRST TROPICAL STORM OF THE SEASON...AL NEARS THE COAST OF NICARAGUA... SUMMARY OF 1100 AM EDT...1500 UTC...INFORMATION ----------------------------------------------- LOCATION...14.9N 74.9W ABOUT 220 MILES...354 KM...SOUTH SOUTHEAST OF KINGSTON JAMAICA ABOUT 280 MILES...450 KM...NORTH OF BARRANQUILLA COLUMBIA ABOUT 510 MILES...820 KM...NORTHEAST OF PANAMA CITY PANAMA MAXIMUM SUSTAINED WINDS...45 MPH...39 KM/HR PRESENT MOVEMENT...WNW OR 276 DEGREES AT 15 MPH...24 KM/HR MINIMUM CENTRAL PRESSURE...999 MB...29.5 INCHES | R6: Keane
A7: 6 | B7: 40299 | C7: 40299.667 | D7: Injected | E7: 40299.667 | F7: INFO | G7: Email | H7: Simcell - National Hurricane Center | I7: KEANE | J7: JOC, All | K7: Tropical Storm Al Update 3 | L7: 5, 15 | M7: Tropical Storm Al Update 3 | P7: ...TROPICAL STORM AL STRENGTHENS AS IT NEARS THE COAST OF NICARAGUA... SUMMARY OF 1700 AM EDT...2100 UTC...INFORMATION ----------------------------------------------- LOCATION...15.30 N 76.20 W ABOUT 188 MILES...303 KM...167 DEGREES...SOUTH-SOUTHEAST OF KINGSTON JAMAICA ABOUT 312 MILES...502 KM...343 DEGREES...NORTH-NORTHWEST OF BARRANQUILLA COLUMBIA MAXIMUM SUSTAINED WINDS...60 MPH...99 KM/HR PRESENT MOVEMENT...WESTERLY OR 275 DEGREES AT 10 MPH...16 KM/HR MINIMUM CENTRAL PRESSURE...997 MB...29.44 INCHES | R7: Keane
A8: 7 | B8: 40299 | C8: 40299.917 | D8: Injected | E8: 40299.917 | F8: INFO | G8: Email | H8: Simcell - National Hurricane Center | I8: KEANE | J8: JOC, All | K8: Tropical Storm Al Update 4 | L8: 5, 15 | M8: Tropical Storm Al Update 4 | P8: ...AL BECOMES A HURRICANE AS IT NEARS THE NORTH COAST OF NICARAGUA... SUMMARY OF 1100 PM EDT...0300 UTC...INFORMATION ----------------------------------------------- LOCATION...15.50 N 77.10 W ABOUT 172 MILES...277 KM...SOUTH SOUTHEAST OF KINGSTON JAMAICA ABOUT 366 MILES...589 KM...NORTH-NORTHWEST OF CARTAGENA COLUMBIA MAXIMUM SUSTAINED WINDS...85 MPH...137 KM/HR PRESENT MOVEMENT...WNW OR 284 DEGREES AT 12 MPH...19 KM/HR MINIMUM CENTRAL PRESSURE...980 MB...28.94 INCHES | R8: Keane
A9: 8 | B9: 40300 | C9: 40300.167 | D9: Injected | E9: 40300.167 | F9: INFO | G9: Email | H9: Simcell - National Hurricane Center | I9: KEANE | J9: JOC, All | K9: Tropical Storm Al Update 4 | L9: 5, 15 | M9: Tropical Storm Al Update 4 | P9: ...AL REMAINS A CAT 1 HURRICANE MOVING EAST TO WEST...SOUTH OF JAMAICA...GAINING STRENGTH... SUMMARY OF 0500 AM EDT...0900 UTC...INFORMATION ----------------------------------------------- LOCATION...15.90 N 78.10 W ABOUT 159 MILES... 255 KM... SOUTH NEGRIL JAMAICA ABOUT 317 MILES... 510 KM... SOUTHEAST OF GEORGE TOWN CAYMAN ISLANDS ABOUT 375 MILES... 604 KM... EAST-NORTHEAST OF PUERTO CABEZAS NICARAGUA MAXIMUM SUSTAINED WINDS...85 MPH...137 KM/HR PRESENT MOVEMENT...WNW OR 282 DEGREES AT 12 MPH...19 KM/HR MINIMUM CENTRAL PRESSURE...979 MB...28.91 INCHES | R9: Keane
A10: 9 | B10: 40300.208 | C10: 40300.208 | D10: Injected | E10: 40300.208 | F10: INFO | K10: Tropical Storm Al Update 5 | M10: Tropical Storm Al Update 5 | R10: Jenne
A11: 10 | B11: 40300 | C11: 40300.417 | D11: Injected | E11: 40300.417 | F11: INFO | G11: Email | H11: Simcell - National Hurricane Center | I11: KEANE | J11: JOC, All | K11: Tropical Storm Al Update 6 | L11: 5, 15 | M11: Tropical Storm Al Update 6 | P11: ... HURRICANE AL TRACKS TOWARD THE YUCATAN... SUMMARY OF 1100 AM EDT...0900 UTC...INFORMATION ----------------------------------------------- LOCATION...16.3N 79.0W ABOUT 257 MILES... 321 KM...SOUTH SOUTHEAST OF GEORGE TOWN CAYMAN ISLANDS ABOUT 137 MILES... 222 KM...SOUTH OF NEGRIL JAMAICA MAXIMUM SUSTAINED WINDS...85 MPH...137 KM/HR PRESENT MOVEMENT...WNW OR 284 DEGREES AT 12 MPH...19 KM/HR MINIMUM CENTRAL PRESSURE...977 MB...28.85 INCHES | R11: Keane
A12: 11 | B12: 40300 | C12: 0.5 | D12: Injected | E12: 40300.5 | F12: RFI | G12: Email | H12: Each Task Force | I12: TF S2 | J12: JOC, J2 | M12: Weather Update/Storm Track | N12: J2 Provides latest Weather and Storm Track to the TFs | P12: Weather RFI from Task Force to J2 | R12: Houlton
A13: 12 | B13: 40300 | C13: 40300.667 | D13: Injected | E13: 40300.667 | F13: INFO | G13: Email | H13: Simcell - National Hurricane Center | I13: KEANE | J13: JOC, All | K13: Tropical Storm Al Update 7 | L13: 5, 15 | M13: Tropical Storm Al Update 7 | P13: ... HURRICANE AL TRACKS TOWARD THE YUCATAN...AS A CATEGORY TWO HURRICANE... SUMMARY OF 0500 AM EDT...0900 UTC...INFORMATION ----------------------------------------------- LOCATION...16.7N 80.0W ABOUT 199 MILES... 321 KM...SOUTH SOUTHEAST OF GEORGE TOWN CAYMAN ISLANDS ABOUT 150 MILES... 241 KM...NEGRIL JAMAICA MAXIMUM SUSTAINED WINDS...105 MPH...169 KM/HR PRESENT MOVEMENT...WNW OR 292 DEGREES AT 12 MPH...19 KM/HR MINIMUM CENTRAL PRESSURE...968 MB...28.59 INCHES | R13: Keane
A14: 13 | B14: 40300 | C14: 40300.917 | D14: Injected | E14: 40300.917 | F14: INFO | G14: Email | H14: Simcell - National Hurricane Center | I14: KEANE | J14: JOC, All | K14: Tropical Storm Al Update 8 | L14: 5, 15 | M14: Tropical Storm Al Update 8 | P14: ... HURRICANE AL GAINS MOMENTUM AS A CATEGORY TWO HURRICANE... SUMMARY OF 2300 PM EDT...0300 UTC...INFORMATION ----------------------------------------------- LOCATION...17.1N 80.9W ABOUT 184 MILES...296 KM...WEST-SOUTHWEST NEGRIL JAMAICA ABOUT 154 MILES...249 KM...SOUTH-SOUTHEAST OF GEORGE TOWN CAYMAN ISLANDS MAXIMUM SUSTAINED WINDS...105 MPH...169 KM/HR PRESENT MOVEMENT...WNW OR 292 DEGREES AT 15 MPH...24 KM/HR MINIMUM CENTRAL PRESSURE...963 MB...28.44 INCHES | R14: Keane
A15: 14 | B15: 40301 | C15: 40301.167 | D15: Injected | E15: 40301.167 | F15: INFO | G15: Email | H15: Simcell - National Hurricane Center | I15: KEANE | J15: JOC, All | K15: Tropical Storm Al Update 9 | L15: 5, 15 | M15: Tropical Storm Al Update 9 | P15: ... HURRICANE AL CONTINUES ON A TRACK TOWARD COZUMEL... SUMMARY OF 0500 AM EDT...0900 UTC...INFORMATION ----------------------------------------------- LOCATION...17.7N 82.1W ABOUT 250 MILES...401 KM...WEST-SOUTHWEST NEGRIL JAMAICA ABOUT 154 MILES...249 KM...SOUTH-SOUTHEAST OF GEORGE TOWN CAYMAN ISLANDS MAXIMUM SUSTAINED WINDS...105 MPH...169 KM/HR PRESENT MOVEMENT...WNW OR 294 DEGREES AT 14 MPH...23 KM/HR MINIMUM CENTRAL PRESSURE...960 MB...28.35 INCHES | R15: Keane
A16: 15 | D16: Omitted | E16: 40301.208 | F16: 31st CHEM BDE - Stands up the CAC and begins tracking storm | G16: Not Injected | R16: Napier
A17: 16 | D17: Omitted | E17: 40301.208 | F17: 31st CHEM BDE - Alert 1165th & 690th O/O Activate | G17: Not Injected | R17: Napier
A18: 17 | B18: 40301 | C18: 40301.292 | D18: Injected | E18: 40301.292 | F18: LNO to SEOC | G18: EMITS | H18: SEOC LNO | I18: SEOC LNO | J18: JOC | M18: NG LNO's to State EOC by 0700 4 May 10 | P18: NG LNO's to State EOC by 0700 4 May 10 | R18: Keane
A19: 18 | B19: 40301.312 | C19: 40301.312 | D19: Injected | E19: 40301.313 | F19: RFI - Holman Prison | G19: Phone Call | H19: JTF-S White Cell (subordinnate commander) | I19: TOMBERLIN | J19: 226 MEB | K19: Holman Prison Blues | M19: Company commander requests guidance on soldier | O19: Inject called in on schedule. Monitoring of JOC message traffic indicates that information apparently did not make it outside of 226 MEB. | P19: Company commander has a soldier who is a prison guard at Holman Prison. Soldier states that he has been directed to remain at prison and not to report to Guard. Indicates rumors of potential inmate takeover and mass escape during hurricane. Soldier/guard states that inmates are apparently planning a takeover while hurricane is in progress, followed by mass escape. There are indications that they may receive external support by an affilated gang. Soldier/guard states that prison officials are discussing requesting security assistance from Guard. | R19: Jenne
A20: 19 | D20: Injected | E20: 40301.314 | F20: MISSION | G20: EMITS | H20: AEMA ESF 5 | I20: SEOC LNO | J20: JOC | L20: 5 | M20: Provide meteorological services to SEOC (AL) | P20: Provide meteorological services to SEOC (AL) | R20: Keane
A21: 20 | D21: Injected | E21: 40301.333 | F21: AEMA Contacts JOC | G21: Phone | H21: AEMA | I21: ALAN PETTY | J21: AL J3 | M21: AEMA Director contacts AL TAG/J3 to discuss hurricane response planning/operations. | P21: AEMA Director contacts AL TAG/J3 to discuss hurricane response planning/operations. AEMA Director states that they are making preliminary plans for possible Alex response operations. Suggests issuing warning orders to MACOMs for potential in-state response operations. | R21: Keane
A22: 21 | B22: 40301 | C22: 0.33333333 | D22: Injected | E22: 40301.335 | F22: MISSION - SASO | G22: Email | H22: simcell-SEOC | I22: SEOC LNO | J22: J35 | K22: SASO | M22: SASO Request | N22: EOC contacts 122CSG | P22: Email Emits message' AEMA SEOC Request ALNG Provide SASO to MAFB | R22: Messer
A23: 22 | B23: 40301 | C23: 0.33333333 | D23: Injected | E23: 40301.335 | F23: MISSION - SEOC LOG CELL | G23: Email | H23: simcell-SEOC | I23: SEOC LNO | J23: J35 | K23: SEOC Log Cell | M23: SEOC Log Cell Request | N23: EOC contacts 122CSG | P23: Email Emits message' AEMA SEOC Request ALNG Provide SEOC Log Cell to Clanton Al. | R23: Messer
A24: 23 | B24: 40301 | C24: 0.35416667 | D24: Deferred | E24: 40301.354 | F24: INFO | G24: Phone | H24: simcell-citizen | I24: HOWARD | J24: Message Center | K24: MVC/ Fatality | M24: Report of Accident | N24: EOC RFIs MACOMS regarding report of accident/vehicles on road | P24: Citizen: I am a retired ARNG member and I just say one of your Humvee's run a stop sign and hit a mini van, and flipped it and it ran off the road. I didn't see anyone get out of either vehicle. I have called 911, just thought you guys wanted to know. | R24: Messer
A25: 24 | D25: Injected | E25: 40301.376 | F25: INFO | G25: Email | H25: JIEE | I25: KAHL | J25: JOC | K25: Set NGB Conference call up on DCO | R25: Kahl
A26: 25 | B26: 40301 | C26: 0.375 | D26: Injected | E26: 40301.376 | F26: INFO | G26: Phone | H26: simcell_LNO | I26: SEOC LNO | J26: J35 | K26: Contra Flow | M26: Informal message from LNO | N26: WARNO to 62nd Troop Command | P26: I just heard that the Governor is probably going to order contra flow on I 65 sometimes tomorrow morning. I will let you know more as I hear it. | R26: Messer
A27: 26 | D27: Injected | E27: 40301.377 | F27: INFO | G27: Email | H27: NGB | I27: KAHL | J27: JOC | K27: Set up event and Share with NGB | R27: Kahl
A28: 27 | D28: Injected | E28: 40301.378 | F28: RFI | G28: JIEE | H28: JIEE | I28: KAHL | J28: JOC | K28: Does the JOC need a JET or PARRT | M28: Request for JET | R28: Kahl
A29: 28 | B29: 40301 | D29: Injected | E29: 40301.378 | F29: INFO | I29: SEOC LNO | M29: The State Emergency Response Team (SERT) is recalled to the State Emergency Operations Center (SEOC (AL)) and activated at Level 1 effective 0900 3 May 2010. | P29: The State Emergency Response Team (SERT) is recalled to the State Emergency Operations Center (SEOC (AL)) and activated at Level 1 effective 0900 3 May 2010. | R29: Keane
A30: 29 | B30: 40301 | C30: 40301.375 | D30: Injected | E30: 40301.379 | F30: MISSION | G30: Email | H30: USPFO, S&S | I30: DENNIS | J30: JOC J4 | M30: USPFO Warehouse to push 20 pallets of MREs and 20 pallets of bottled water to Ft McClellan, AL (pre-positioning for soldier support). | P30: USPFO Warehouse to push 20 pallets of MREs and 20 pallets of bottled water to Ft McClellan, AL (pre-positioning for soldier support). | Q30: USPFO Warehouse SOP, SA only | R30: Keane
A31: 30 | B31: 40301 | D31: Injected | E31: 40301.381 | F31: INFO - Evacuation | I31: SEOC LNO | M31: AEMA recommends voluntary evacuation of Baldwin and Mobile counties. | P31: AEMA recommends voluntary evacuation of Baldwin and Mobile counties. Voluntary evacuations recommended for citizens living in mobile homes for the following counties: Washington, Clarke, Monroe, Conecuh, Escambia, Covington, Geneva, and Houston. | R31: Keane
A32: 31 | B32: 40301 | D32: Injected | E32: 40301.381 | F32: INFO | I32: KEANE | M32: JFHQ activates JTF-South (FTUS) Primary Staff (LNO's)and local units for possible support | P32: JFHQ activates JTF-South (FTUS) Primary Staff (LNO's)and local units for possible support | R32: Keane
A33: 32 | D33: Injected | E33: 40301.385 | F33: INFO | G33: Email | H33: MED DET | I33: BENTON | J33: SPS MED & J1 | K33: 1 Soldier found HIV positive in the 226th MEB after a periodic health assessment (PHA) performed by the medical detachment, from 10-11 Apr 10 SRP in Mobile. | M33: 1 Soldier found HIV positive in the 226th MEB after a periodic health assessment (PHA) performed by the medical detachment, from 10-11 Apr 10 SRP in Mobile. | P33: 1 Soldier found HIV positive in the 226th MEB after a periodic health assessment (PHA) performed by the medical detachment, from 10-11 Apr 10 SRP in Mobile. | R33: Benton
A34: 33 | D34: Injected | E34: 40301.385 | I34: P. MCDONALD | J34: JOC MSG CTR | K34: Army National Guard CAT requests Alabama review resources available IOT support FL with 1X Med Trk Co and 1X DS/GS Maint Co. | O34: At 0939 hours LTC Small , ARNG CAT, contacted MAJ Davis @ 334.273.3547 after several attempts to other numbers provided by SGT Vice. He is to advise. At 1114 hours, MAJ Davis advises TAG-AL requests a 48 hour hold before approving the EMAC request. | P34: Army National Guard CAT requests Alabama review resources available IOT support FL with 1X Med Trk Co and 1X DS/GS Maint Co. | R34: McDonald
A35: 34 | D35: Injected | E35: 40301.386 | F35: INFO | G35: Telephone Call | H35: STATE SURGEON | I35: BENTON | J35: SPS MED | K35: All JTFs must perform a medical readiness screening of the potential personnel being considered for DSCA support mission to ensure that they have a current PHA, Dental Exam, Routine Adult Immunizations (to include H1N1) and have no outstanding noon-deployable medical conditions. Submit status report back to SPS.MED NLT 1200 4 May 10. | M35: All JTFs must perform a medical readiness screening of the potential personnel being considered for DSCA support mission to ensure that they have a current PHA, Dental Exam, Routine Adult Immunizations (to include H1N1) and have no outstanding noon-deployable medical conditions. Submit status report back to SPS.MED NLT 1200 4 May 10. | P35: All JTFs must perform a medical readiness screening of the potential personnel being considered for DSCA support mission to ensure that they have a current PHA, Dental Exam, Routine Adult Immunizations (to include H1N1) and have no outstanding noon-deployable medical conditions. Submit status report back to SPS.MED NLT 1200 4 May 10. | R35: Benton
A36: 35 | B36: 40301 | D36: Injected | E36: 40301.387 | F36: INFO | I36: SEOC LNO | M36: TF South gets notification of pending activation | P36: TF South gets notification of pending activation | R36: Keane
A37: 36 | D37: Injected | E37: 40301.389 | I37: P. MCDONALD | K37: Army National Guard CAT requests Alabama review resources available IOT support TX with 1x Light/Medium Truck Company and 1x POL Co. | O37: At 0923 hours LTC Small, ARNG CAT, contacted MSG Woodall @ 334.213.7748 and he took message and would have someone return our call. At 1007 hours called MSG Woodall and advised no one had called. Left another message. At 1114 hours MAJ Davis, AL JOC returned call and received request. Will advise. At 1715 hours, MAJ Davis advises TAG will concur with request but requests a 48 hours delay for the EMAC request. | P37: Army National Guard CAT requests Alabama review resources available IOT support TX with 1x Light/Medium Truck Company and 1x POL Co. | R37: McDonald
A38: 37 | B38: 40301 | D38: Injected | E38: 40301.39 | F38: INFO | I38: SEOC LNO | M38: FEMA Region JFO ERT-A will deploy to AEMA on 4 May about 1200, FEMA Region 9 DCO will serve as JFO-AL DCO | P38: FEMA Region JFO ERT-A will deploy to AEMA on 4 May about 1200, FEMA Region 9 DCO will serve as JFO-AL DCO | R38: Keane
A39: 38 | B39: 40301 | D39: Injected | E39: 40301.39 | F39: MISSION | I39: SEOC LNO | M39: Deploy SERT (AL) LNOs to Mobile and Baldwin counties NLT 4 May 1800. | P39: Deploy SERT (AL)LNOs to Mobile and Baldwin counties NLT 4 May 1800. | R39: Keane
A40: 39 | D40: Omitted | E40: 40301.392 | K40: Army National Guard CAT requests Alabama review resources available IOT support Tx and LA with unfilled EMAC Requests. | P40: Army National Guard CAT requests Alabama review resources available IOT support Tx and LA with unfilled EMAC Requests.
...

Sheet MSEL INFO ONLY
A1: MSEL NUMBER | B1: DATE | C1: Time | D1: INJECT DTG | E1: INJECT MODE | F1: SEND FROM (Simulated) | G1: INJECTED BY | H1: SEND TO | I1: STORYLINE/THREAD | J1: ESF | K1: DESCRIPTION | L1: INJECT MODE | M1: OBJ. (SA, RFA, RFI, NGA - Action that generates planning or activity) | N1: INITIATED BY | O1: Inject Entry (JOC, JTF-N/S, DRU, AEMA, Staff, Leadership, Other) | P1: NARRATIVE | Q1: BACKGROUND INFORMATION
E2: Weather | K2: Weather
E3: AEMA SA/RFI | K3: AEMA SA/RFI
E4: Weather and Threat related | K4: Weather and Threat related
E5: AEMA Mission Tasker | K5: AEMA Mission Tasker
E6: JFHQ Staff | K6: JFHQ Staff
E7: JTF/Task Force/ DRU RFI/RFA | K7: JTF/Task Force/ DRU RFI/RFA
E8: EMAC Related | K8: EMAC Related
B10: 41399 | C10: 41399.167 | D10: 41398.167 | E10: Email | F10: Simcell - National Hurricane Center | G10: Keane | H10: JOC, All | I10: Tropical Depression One Forms | J10: 5, 15 | K10: Tropical Depression One Forms | L10: EMITS or Email | M10: SA | N10: White Cell | O10: JOC | P10: On 04 May, 0400 HRS CDT, The National Hurricane Center issues Tropical Depression Advisory "One". Current Location 14.5 N 74.1 W Max Sustained Wind 30mph
B11: 41398.208 | C11: 41398.208 | D11: 41398.213 | E11: Not Injected - MSEL Planning Info only | I11: Background Information (Hurricane Synchronization Matrix) | K11: J-1 / Safety - Begin statewide push on Hurricane and Tornado | L11: EMITS or Email | M11: SA | N11: White Cell | O11: JOC
B12: 41398.208 | C12: 41398.208 | D12: 41398.213 | E12: Not Injected - MSEL Planning Info only | I12: Background Information (Hurricane Synchronization Matrix) | K12: J-1 / Strength - Review J-1 / Medical, Avn/Trans, EN, MP, LG and SIG/IT Personnel Assets | L12: EMITS or Email | M12: SA | N12: White Cell | O12: JOC
B13: 41398.208 | C13: 41398.208 | D13: 41398.214 | E13: Not Injected - MSEL Planning Info only | I13: Background Information (Hurricane Synchronization Matrix) | K13: J-4 / Class I - Review MRE DOS, ensure sufficient 2 DOS per JTF | L13: EMITS or Email | M13: SA | N13: White Cell | O13: JOC
B14: 41398.208 | C14: 41398.208 | D14: 41398.215 | E14: Not Injected - MSEL Planning Info only | I14: Background Information (Hurricane Synchronization Matrix) | K14: J-4 / Class III - Link up with SPDOF and verify that fuel contracts listed are valid | L14: EMITS or Email | M14: SA | N14: White Cell | O14: JOC
B15: 41398.208 | C15: 41398.208 | D15: 41398.215 | E15: Not Injected - MSEL Planning Info only | I15: Background Information (Hurricane Synchronization Matrix) | K15: J-4 / Class IX - Verify status of CL IX push package. Verify maint status of equipement | L15: EMITS or Email | M15: SA | N15: White Cell | O15: JOC
B16: 41398.208 | C16: 41398.208 | D16: 41398.216 | E16: Not Injected - MSEL Planning Info only | I16: Background Information (Hurricane Synchronization Matrix) | K16: J-4 / Class V - Review requirements with FMARNGTC ATP. Verify sufficient on hand | L16: EMITS or Email | M16: SA | N16: White Cell | O16: JOC
B17: 41398.208 | C17: 41398.208 | D17: 41398.217 | E17: Not Injected - MSEL Planning Info only | I17: Background Information (Hurricane Synchronization Matrix) | K17: J-4 / Class VII - Review initial density report. Determine shortages and X-Level | L17: EMITS or Email | M17: SA | N17: White Cell | O17: JOC
B18: 41398.208 | C18: 41398.208 | D18: 41398.217 | E18: Not Injected - MSEL Planning Info only | I18: Background Information (Hurricane Synchronization Matrix) | K18: J-4 / Class VIII - Review quantities available, specifically IV fluids for CLS Bags | L18: EMITS or Email | M18: SA | N18: White Cell | O18: JOC
B19: 41398.208 | C19: 41398.208 | D19: 41398.218 | E19: Not Injected - MSEL Planning Info only | I19: Background Information (Hurricane Synchronization Matrix) | K19: J-4 / Class II - Inventory DERT, note shortages and makeup shortages | L19: EMITS or Email | M19: SA | N19: White Cell | O19: JOC
B20: 41398.208 | C20: 41398.208 | D20: 41398.219 | E20: Not Injected - MSEL Planning Info only | I20: Background Information (Hurricane Synchronization Matrix) | K20: J-4 / Misc Funding - Review available funds for use during contingency operations. Monitor funding levels. | L20: EMITS or Email | M20: SA | N20: White Cell | O20: JOC
B21: 41398.208 | C21: 41398.208 | D21: 41398.219 | E21: Not Injected - MSEL Planning Info only | I21: Background Information (Hurricane Synchronization Matrix) | K21: J-4 / Transportation - Prepare to issue convoy orders to affected units to strike sector. Verify status of enablers | L21: EMITS or Email | M21: SA | N21: White Cell | O21: JOC
B22: 41398.208 | C22: 41398.208 | D22: 41398.22 | E22: Not Injected - MSEL Planning Info only | I22: Background Information (Hurricane Synchronization Matrix) | K22: JTF-187 FW - FTUS Hurricane Tracking | L22: EMITS or Email | M22: SA | N22: White Cell | O22: JOC
... B36: 41399.208 | C36: 41399.208 | D36: 41398.217 | E36: Not Injected - MSEL Planning Info only | I36: Background Information (Hurricane Synchronization Matrix) | K36: White Cell JTF-Tarpon - Test alert roster for key personnel TPFDD to JTF-S | L36: EMITS or Email | M36: SA | N36: White Cell | O36: JOC
B37: 41399 | C37: 41399.417 | D37: 41398.417 | E37: Email | F37: Simcell - National Hurricane Center | G37: Keane | H37: JOC, All | I37: Tropical Storm Al Update 2 | J37: 5, 15 | K37: Tropical Storm Al Update 2 | L37: EMITS or Email | M37: SA | N37: White Cell | O37: JOC | P37: ...FIRST TROPICAL STORM OF THE SEASON...AL NEARS THE COAST OF NICARAGUA... SUMMARY OF 1100 AM EDT...1500 UTC...INFORMATION ----------------------------------------------- LOCATION...14.9N 74.9W ABOUT 220 MILES...354 KM...SOUTH SOUTHEAST OF KINGSTON JAMA
B38: 41399 | C38: 41399.667 | D38: 41398.667 | E38: Email | F38: Simcell - National Hurricane Center | G38: Keane | H38: JOC, All | I38: Tropical Storm Al Update 3 | J38: 5, 15 | K38: Tropical Storm Al Update 3 | L38: EMITS or Email | M38: SA | N38: White Cell | O38: JOC | P38: ...TROPICAL STORM AL STRENGTHENS AS IT NEARS THE COAST OF NICARAGUA... SUMMARY OF 1700 AM EDT...2100 UTC...INFORMATION ----------------------------------------------- LOCATION...15.30 N 76.20 W ABOUT 188 MILES...303 KM...167 DEGREES...SOUTH-SOUTHEAST OF
B39: 41399 | C39: 41399.917 | D39: 41398.917 | E39: Email | F39: Simcell - National Hurricane Center | H39: JOC, All | I39: Tropical Storm Al Update 4 | J39: 5, 15 | K39: Tropical Storm Al Update 4 | L39: EMITS or Email | M39: SA | N39: White Cell | O39: JOC | P39: ...AL BECOMES A HURRICANE AS IT NEARS THE NORTH COAST OF NICARAGUA... SUMMARY OF 1100 PM EDT...0300 UTC...INFORMATION ----------------------------------------------- LOCATION...15.50 N 77.10 W ABOUT 172 MILES...277 KM...SOUTH SOUTHEAST OF KINGSTON JAMAI
B40: 41400.208 | C40: 41400.208 | D40: 41399.208 | E40: Not Injected - MSEL Planning Info only | I40: Tropical Storm Al Update 5 | K40: Tropical Storm Al Update 5 | L40: EMITS or Email | M40: SA | N40: White Cell | O40: JOC | P40: ... AT 5 AM AST...0900Z...AL BECOMES A HURRICANE AS IT NEARS THE NORTH COAST OF NICARAGUALOCATION...15.90 N 78.10 W ABOUT 159 MILES... 255 KM... SOUTH NEGRIL JAMAICA ABOUT 375 MILES... 604 KM... EAST-NORTHEAST OF PUERTO CABEZAS NICARAGUA MAXIMUM SUSTAINED WINDS...85 MPH...137 KM/HR PRESENT MOVEMENT...WNW OR 275 DEGREES AT 12 MPH...19 KM/HR
B41: 41400.208 | C41: 41400.208 | D41: 41399.209 | E41: Not Injected - MSEL Planning Info only | I41: Background Information (Hurricane Synchronization Matrix) | K41: 187 FW - Issue BPT deploy order to 122d ASG and alert LNOs | L41: EMITS or Email | M41: SA | N41: White Cell | O41: JOC
B42: 41399.208 | C42: 41399.208 | D42: 41399.21 | E42: Not Injected - MSEL Planning Info only | I42: Background Information (Hurricane Synchronization Matrix) | K42: 167 TSC - Implement CEMP 10-2 Annex B | L42: EMITS or Email | M42: SA | N42: White Cell | O42: JOC
B43: 41399.208 | C43: 41399.208 | D43: 41399.21 | E43: Not Injected - MSEL Planning Info only | I43: Background Information (Hurricane Synchronization Matrix) | K43: 20 SF - Dispatch LNO to State JOC, Cooridnate with 131st AVN | L43: EMITS or Email | M43: SA | N43: White Cell | O43: JOC
B44: 41399.208 | C44: 41399.208 | D44: 41399.211 | E44: Not Injected - MSEL Planning Info only | I44: Background Information (Hurricane Synchronization Matrix) | K44: JTF Tarpon TC - Issue WARN ORDER 1, CMC Prep | L44: EMITS or Email | M44: SA | N44: White Cell | O44: JOC
B45: 41399.208 | C45: 41399.208 | D45: 41399.212 | E45: Not Injected - MSEL Planning Info only | I45: Background Information (Hurricane Synchronization Matrix) | K45: AEMA SEOC - Alert Alabama Mutual Aid System and County Liaisons | L45: EMITS or Email | M45: SA | N45: White Cell | O45: JOC
B46: 41399.208 | C46: 41399.208 | D46: 41399.213 | E46: Not Injected - MSEL Planning Info only | I46: Background Information (Hurricane Synchronization Matrix) | K46: AEMA SEOC -Activate Logistics Staging at Maxwell AFB | L46: EMITS or Email | M46: SA | N46: White Cell | O46: JOC
B47: 41399.208 | C47: 41399.208 | D47: 41399.213 | E47: Not Injected - MSEL Planning Info only | I47: Background Information (Hurricane Synchronization Matrix) | K47: AEMA SEOC -Activate Resource Contracts for Security, Food, Ice and Water | L47: EMITS or Email | M47: SA | N47: White Cell | O47: JOC
B48: 41399.208 | C48: 41399.208 | D48: 41399.214 | E48: Not Injected - MSEL Planning Info only | I48: Background Information (Hurricane Synchronization Matrix) | K48: AEMA SEOC -Begin Opening Shelters | L48: EMITS or Email | M48: SA | N48: White Cell | O48: JOC
B49: 41399.208 | C49: 41399.208 | D49: 41399.215 | E49: Not Injected - MSEL Planning Info only | I49: Background Information (Hurricane Synchronization Matrix) | K49: AEMA SEOC -Begin Public Information Briefings | L49: EMITS or Email | M49: SA | N49: White Cell | O49: JOC
B50: 41399.208 | C50: 41399.208 | D50: 41399.215 | E50: Not Injected - MSEL Planning Info only | I50: Background Information (Hurricane Synchronization Matrix) | K50: AEMA SEOC -Begin Twice Daily Situation Updates | L50: EMITS or Email | M50: SA | N50: White Cell | O50: JOC
B51: 41399.208 | C51: 41399.208 | D51: 41399.216 | E51: Not Injected - MSEL Planning Info only | I51: Background Information (Hurricane Synchronization Matrix) | K51: AEMA SEOC -Participate in FEMA and Hurricane Liaison Team Conference Calls | L51: EMITS or Email | M51: SA | N51: White Cell | O51: JOC
B52: 41399.208 | C52: 41399.208 | D52: 41399.217 | E52: Not Injected - MSEL Planning Info only | I52: Background Information (Hurricane Synchronization Matrix) | K52: AEMA SEOC -Request Shelter Generators | L52: EMITS or Email | M52: SA | N52: White Cell | O52: JOC
... B67: 41399.208 | C67: 41399.208 | D67: 41399.227 | E67: Not Injected - MSEL Planning Info only | I67: Background Information (Hurricane Synchronization Matrix) | K67: LNO'S - ALERT LNOs | L67: EMITS or Email | M67: NGA | N67: White Cell | O67: JOC
B68: 41399 | C68: 41399.417 | D68: 41399.417 | E68: Email | F68: Simcell - National Hurricane Center | H68: JOC, All | I68: Tropical Storm Al Update 6 | J68: 5, 15 | K68: Tropical Storm Al Update 6 | L68: EMITS or Email | M68: SA | N68: White Cell | O68: JOC | P68: ... HURRICANE AL TRACKS TOWARD THE YUCATAN... SUMMARY OF 1100 AM EDT...0900 UTC...INFORMATION ----------------------------------------------- LOCATION...16.3N 79.0W ABOUT 257 MILES... 321 KM...SOUTH SOUTHEAST OF GEORGE TOWN CAYMAN ISLANDS ABOUT 137 MIL
...

Sheet Backup
A1: Hurricane Scenario
A2: Master Scenario Events List (MSEL)
A3: MSEL NUMBER | B3: DATE | C3: INJECT DTG | D3: SUBJECT | E3: INJECT MODE | F3: SEND FROM (Simulated) | G3: INJECTED BY | H3: SEND TO | I3: STORYLINE/THREAD | J3: ESF | K3: DESCRIPTION | L3: EXPECTED ACTION | M3: NOTES/REMARKS | N3: IMPLEMENTER (Actual Narrative) | O3: BACKGROUND INFORMATION | P3: Inject Author

Sheet PRINT_SMALL
A1: MSEL # | B1: STATUS | C1: DTG | D1: SUBJECT | E1: INJECT MODE: / SEND FROM: / INJECTED BY: / SEND TO: | F1: STORYLINE / DESCRIPTION / NOTES & REMARKS / BACKGROUND INFO | G1: IMPLEMENTER | H1: EXPECTED ACTIONS | I1: AUTHOR
A2: ='Excercise - Al '!A2 -> 1 | B2: Ready to Inject | C2: ='Excercise - Al '!E2 -> 40298.208 | D2: =IF('Excercise - Al '!F2<>0,'Excercise - Al '!F2,"") -> 31st CHEM BDE - Notifies select staff | E2: =IF('Excercise - Al '!G2<>"","MODE: "&'Excercise - Al '!G2,"")&IF('Excercise - Al '!H2<>""," FROM: "&'Excercise - Al '!H2,"")&IF('Excercise - Al '!I2<>""," INJECTED BY: "&'Excercise - Al '!I2,"")&IF('Excercise - Al '!J2<>""," SEND TO: "&'Excercise - Al '!J2,"") -> MODE: Not Injected | F2: =IF('Excercise - Al '!K2<>"","STORYLINE: "&'Excercise - Al '!K2,"")&IF('Excercise - Al '!M2<>""," DESCRIPTION: "&'Excercise - Al '!M2,"")&IF('Excercise - Al '!O2<>""," NOTES/REMARKS: "&'Excercise - Al '!O2,"")&IF('Excercise - Al '!Q2<>""," BACKGROUND INFO: "&'Excercise - Al '!Q2,"") | G2: =IF('Excercise - Al '!P2<>"","IMPLEMENTER: "&'Excercise - Al '!P2,"") | H2: =IF('Excercise - Al '!N2<>"","EXPECTED ACTIONS: "&'Excercise - Al '!N2,"") | I2: ='Excercise - Al '!R2 -> Napier
A3: ='Excercise - Al '!A3 -> 2 | C3: ='Excercise - Al '!E3 -> 40299.167 | D3: =IF('Excercise - Al '!F3<>0,'Excercise - Al '!F3,"") -> INFO | E3: =IF('Excercise - Al '!G3<>"","MODE: "&'Excercise - Al '!G3,"")&IF('Excercise - Al '!H3<>""," FROM: "&'Excercise - Al '!H3,"")&IF('Excercise - Al '!I3<>""," INJECTED BY: "&'Excercise - Al '!I3,"")&IF('Excercise - Al '!J3<>""," SEND TO: "&'Excercise - Al '!J3,"") -> MODE: Email FROM: Simcell - National Hurricane Center INJECTED BY: KEANE SEND TO: JOC, All | F3: =IF('Excercise - Al '!K3<>"","STORYLINE: "&'Excercise - Al '!K3,"")&IF('Excercise - Al '!M3<>""," DESCRIPTION: "&'Excercise - Al '!M3,"")&IF('Excercise - Al '!O3<>""," NOTES/REMARKS: "&'Excercise - Al '!O3,"")&IF('Excercise - Al '!Q3<>""," BACKGROUND INFO: "&'Excercise - Al '!Q3,"") -> STORYLINE: Tropical Depression One Forms DESCRIPTION: Tropical Depression One Forms | G3: =IF('Excercise - Al '!P3<>"","IMPLEMENTER: "&'Excercise - Al '!P3,"") -> IMPLEMENTER: On 01 May, 0400 HRS CDT, The National Hurricane Center issues Tropical Depression Advisory "One". Current Location 14.5 N 74.1 W Max Sustained Wind 30mph | H3: =IF('Excercise - Al '!N3<>"","EXPECTED ACTIONS: "&'Excercise - Al '!N3,"") | I3: ='Excercise - Al '!R3 -> Keane
A4: ='Excercise - Al '!A4 -> 3 | C4: ='Excercise - Al '!E4 -> 40299.208 | D4: =IF('Excercise - Al '!F4<>0,'Excercise - Al '!F4,"") -> 31st CHEM BDE - Telecon with unit CDRs and issue verbal WARNO | E4: =IF('Excercise - Al '!G4<>"","MODE: "&'Excercise - Al '!G4,"")&IF('Excercise - Al '!H4<>""," FROM: "&'Excercise - Al '!H4,"")&IF('Excercise - Al '!I4<>""," INJECTED BY: "&'Excercise - Al '!I4,"")&IF('Excercise - Al '!J4<>""," SEND TO: "&'Excercise - Al '!J4,"") -> MODE: Not Injected | F4: =IF('Excercise - Al '!K4<>"","STORYLINE: "&'Excercise - Al '!K4,"")&IF('Excercise - Al '!M4<>""," DESCRIPTION: "&'Excercise - Al '!M4,"")&IF('Excercise - Al '!O4<>""," NOTES/REMARKS: "&'Excercise - Al '!O4,"")&IF('Excercise - Al '!Q4<>""," BACKGROUND INFO: "&'Excercise - Al '!Q4,"") | G4: =IF('Excercise - Al '!P4<>"","IMPLEMENTER: "&'Excercise - Al '!P4,"") | H4: =IF('Excercise - Al '!N4<>"","EXPECTED ACTIONS: "&'Excercise - Al '!N4,"") | I4: ='Excercise - Al '!R4 -> Napier
A5: ='Excercise - Al '!A5 -> 4 | C5: ='Excercise - Al '!E5 -> 40299.208 | D5: =IF('Excercise - Al '!F5<>0,'Excercise - Al '!F5,"") -> 31st CHEM BDE - Test alert roster of key personnel and for the 1165th and 690th | E5: =IF('Excercise - Al '!G5<>"","MODE: "&'Excercise - Al '!G5,"")&IF('Excercise - Al '!H5<>""," FROM: "&'Excercise - Al '!H5,"")&IF('Excercise - Al '!I5<>""," INJECTED BY: "&'Excercise - Al '!I5,"")&IF('Excercise - Al '!J5<>""," SEND TO: "&'Excercise - Al '!J5,"") -> MODE: Not Injected | F5: =IF('Excercise - Al '!K5<>"","STORYLINE: "&'Excercise - Al '!K5,"")&IF('Excercise - Al '!M5<>""," DESCRIPTION: "&'Excercise - Al '!M5,"")&IF('Excercise - Al '!O5<>""," NOTES/REMARKS: "&'Excercise - Al '!O5,"")&IF('Excercise - Al '!Q5<>""," BACKGROUND INFO: "&'Excercise - Al '!Q5,"") | G5: =IF('Excercise - Al '!P5<>"","IMPLEMENTER: "&'Excercise - Al '!P5,"") | H5: =IF('Excercise - Al '!N5<>"","EXPECTED ACTIONS: "&'Excercise - Al '!N5,"") | I5: ='Excercise - Al '!R5 -> Napier
A6: ='Excercise - Al '!A6 -> 5 | C6: ='Excercise - Al '!E6 -> 40299.417 | D6: =IF('Excercise - Al '!F6<>0,'Excercise - Al '!F6,"") -> INFO | E6: =IF('Excercise - Al '!G6<>"","MODE: "&'Excercise - Al '!G6,"")&IF('Excercise - Al '!H6<>""," FROM: "&'Excercise - Al '!H6,"")&IF('Excercise - Al '!I6<>""," INJECTED BY: "&'Excercise - Al '!I6,"")&IF('Excercise - Al '!J6<>""," SEND TO: "&'Excercise - Al '!J6,"") -> MODE: Email FROM: Simcell - National Hurricane Center INJECTED BY: KEANE SEND TO: JOC, All | F6: =IF('Excercise - Al '!K6<>"","STORYLINE: "&'Excercise - Al '!K6,"")&IF('Excercise - Al '!M6<>""," DESCRIPTION: "&'Excercise - Al '!M6,"")&IF('Excercise - Al '!O6<>""," NOTES/REMARKS: "&'Excercise - Al '!O6,"")&IF('Excercise - Al '!Q6<>""," BACKGROUND INFO: "&'Excercise - Al '!Q6,"") -> STORYLINE: Tropical Storm Al Update 2 DESCRIPTION: Tropical Storm Al Update 2 | G6: =IF('Excercise - Al '!P6<>"","IMPLEMENTER: "&'Excercise - Al '!P6,"") -> IMPLEMENTER: ...FIRST TROPICAL STORM OF THE SEASON...AL NEARS THE COAST OF NICARAGUA... SUMMARY OF 1100 AM EDT...1500 UTC...INFORMATION ----------------------------------------------- LOCATION...14.9N 74.9W ABOUT 220 MILES...354 KM...SOUTH SOUTHEAST OF KINGSTON JAMAICA ABOUT 280 MILES...450 KM...NORTH OF BARRANQUILLA COLUMBIA ABOUT 510 MILES...820 KM...NORTHEAST OF PANAMA CITY PANAMA MAXIMUM SUSTAINED WINDS...45 MPH...39 KM/HR PRESENT MOVEMENT...WNW OR 276 DEGREES AT 15 MPH...24 KM/HR MINIMUM CENTRAL PRESSURE...999 MB...29.5 INCHES | H6: =IF('Excercise - Al '!N6<>"","EXPECTED ACTIONS: "&'Excercise - Al '!N6,"") | I6: ='Excercise - Al '!R6 -> Keane
A7: ='Excercise - Al '!A7 -> 6 | C7: ='Excercise - Al '!E7 -> 40299.667 | D7: =IF('Excercise - Al '!F7<>0,'Excercise - Al '!F7,"") -> INFO | E7: =IF('Excercise - Al '!G7<>"","MODE: "&'Excercise - Al '!G7,"")&IF('Excercise - Al '!H7<>""," FROM: "&'Excercise - Al '!H7,"")&IF('Excercise - Al '!I7<>""," INJECTED BY: "&'Excercise - Al '!I7,"")&IF('Excercise - Al '!J7<>""," SEND TO: "&'Excercise - Al '!J7,"") -> MODE: Email FROM: Simcell - National Hurricane Center INJECTED BY: KEANE SEND TO: JOC, All | F7: =IF('Excercise - Al '!K7<>"","STORYLINE: "&'Excercise - Al '!K7,"")&IF('Excercise - Al '!M7<>""," DESCRIPTION: "&'Excercise - Al '!M7,"")&IF('Excercise - Al '!O7<>""," NOTES/REMARKS: "&'Excercise - Al '!O7,"")&IF('Excercise - Al '!Q7<>""," BACKGROUND INFO: "&'Excercise - Al '!Q7,"") -> STORYLINE: Tropical Storm Al Update 3 DESCRIPTION: Tropical Storm Al Update 3 | G7: =IF('Excercise - Al '!P7<>"","IMPLEMENTER: "&'Excercise - Al '!P7,"") -> IMPLEMENTER: ...TROPICAL STORM AL STRENGTHENS AS IT NEARS THE COAST OF NICARAGUA... SUMMARY OF 1700 AM EDT...2100 UTC...INFORMATION ----------------------------------------------- LOCATION...15.30 N 76.20 W ABOUT 188 MILES...303 KM...167 DEGREES...SOUTH-SOUTHEAST OF KINGSTON JAMAICA ABOUT 312 MILES...502 KM...343 DEGREES...NORTH-NORTHWEST OF BARRANQUILLA COLUMBIA MAXIMUM SUSTAINED WINDS...60 MPH...99 KM/HR PRESENT MOVEMENT...WESTERLY OR 275 DEGREES AT 10 MPH...16 KM/HR MINIMUM CENTRAL PRESSURE...997 MB...29.44 INCHES | H7: =IF('Excercise - Al '!N7<>"","EXPECTED ACTIONS: "&'Excercise - Al '!N7,"") | I7: ='Excercise - Al '!R7 -> Keane
A8: ='Excercise - Al '!A8 -> 7 | C8: ='Excercise - Al '!E8 -> 40299.917 | D8: =IF('Excercise - Al '!F8<>0,'Excercise - Al '!F8,"") -> INFO | E8: =IF('Excercise - Al '!G8<>"","MODE: "&'Excercise - Al '!G8,"")&IF('Excercise - Al '!H8<>""," FROM: "&'Excercise - Al '!H8,"")&IF('Excercise - Al '!I8<>""," INJECTED BY: "&'Excercise - Al '!I8,"")&IF('Excercise - Al '!J8<>""," SEND TO: "&'Excercise - Al '!J8,"") -> MODE: Email FROM: Simcell - National Hurricane Center INJECTED BY: KEANE SEND TO: JOC, All | F8: =IF('Excercise - Al '!K8<>"","STORYLINE: "&'Excercise - Al '!K8,"")&IF('Excercise - Al '!M8<>""," DESCRIPTION: "&'Excercise - Al '!M8,"")&IF('Excercise - Al '!O8<>""," NOTES/REMARKS: "&'Excercise - Al '!O8,"")&IF('Excercise - Al '!Q8<>""," BACKGROUND INFO: "&'Excercise - Al '!Q8,"") -> STORYLINE: Tropical Storm Al Update 4 DESCRIPTION: Tropical Storm Al Update 4 | G8: =IF('Excercise - Al '!P8<>"","IMPLEMENTER: "&'Excercise - Al '!P8,"") -> IMPLEMENTER: ...AL BECOMES A HURRICANE AS IT NEARS THE NORTH COAST OF NICARAGUA... SUMMARY OF 1100 PM EDT...0300 UTC...INFORMATION ----------------------------------------------- LOCATION...15.50 N 77.10 W ABOUT 172 MILES...277 KM...SOUTH SOUTHEAST OF KINGSTON JAMAICA ABOUT 366 MILES...589 KM...NORTH-NORTHWEST OF CARTAGENA COLUMBIA MAXIMUM SUSTAINED WINDS...85 MPH...137 KM/HR PRESENT MOVEMENT...WNW OR 284 DEGREES AT 12 MPH...19 KM/HR MINIMUM CENTRAL PRESSURE...980 MB...28.94 INCHES | H8: =IF('Excercise - Al '!N8<>"","EXPECTED ACTIONS: "&'Excercise - Al '!N8,"") | I8: ='Excercise - Al '!R8 -> Keane
A9: ='Excercise - Al '!A9 -> 8 | C9: ='Excercise - Al '!E9 -> 40300.167 | D9: =IF('Excercise - Al '!F9<>0,'Excercise - Al '!F9,"") -> INFO | E9: =IF('Excercise - Al '!G9<>"","MODE: "&'Excercise - Al '!G9,"")&IF('Excercise - Al '!H9<>""," FROM: "&'Excercise - Al '!H9,"")&IF('Excercise - Al '!I9<>""," INJECTED BY: "&'Excercise - Al '!I9,"")&IF('Excercise - Al '!J9<>""," SEND TO: "&'Excercise - Al '!J9,"") -> MODE: Email FROM: Simcell - National Hurricane Center INJECTED BY: KEANE SEND TO: JOC, All | F9: =IF('Excercise - Al '!K9<>"","STORYLINE: "&'Excercise - Al '!K9,"")&IF('Excercise - Al '!M9<>""," DESCRIPTION: "&'Excercise - Al '!M9,"")&IF('Excercise - Al '!O9<>""," NOTES/REMARKS: "&'Excercise - Al '!O9,"")&IF('Excercise - Al '!Q9<>""," BACKGROUND INFO: "&'Excercise - Al '!Q9,"") -> STORYLINE: Tropical Storm Al Update 4 DESCRIPTION: Tropical Storm Al Update 4 | G9: =IF('Excercise - Al '!P9<>"","IMPLEMENTER: "&'Excercise - Al '!P9,"") -> IMPLEMENTER: ...AL REMAINS A CAT 1 HURRICANE MOVING EAST TO WEST...SOUTH OF JAMAICA...GAINING STRENGTH... SUMMARY OF 0500 AM EDT...0900 UTC...INFORMATION ----------------------------------------------- LOCATION...15.90 N 78.10 W ABOUT 159 MILES... 255 KM... SOUTH NEGRIL JAMAICA ABOUT 317 MILES... 510 KM... SOUTHEAST OF GEORGE TOWN CAYMAN ISLANDS ABOUT 375 MILES... 604 KM... EAST-NORTHEAST OF PUERTO CABEZAS NICARAGUA MAXIMUM SUSTAINED WINDS...85 MPH...137 KM/HR PRESENT MOVEMENT...WNW OR 282 DEGREES AT 12 MPH...19 KM/HR MINIMUM CENTRAL PRESSURE...979 MB...28.91 INCHES | H9: =IF('Excercise - Al '!N9<>"","EXPECTED ACTIONS: "&'Excercise - Al '!N9,"") | I9: ='Excercise - Al '!R9 -> Keane
A10: ='Excercise - Al '!A10 -> 9 | C10: ='Excercise - Al '!E10 -> 40300.208 | D10: =IF('Excercise - Al '!F10<>0,'Excercise - Al '!F10,"") -> INFO | E10: =IF('Excercise - Al '!G10<>"","MODE: "&'Excercise - Al '!G10,"")&IF('Excercise - Al '!H10<>""," FROM: "&'Excercise - Al '!H10,"")&IF('Excercise - Al '!I10<>""," INJECTED BY: "&'Excercise - Al '!I10,"")&IF('Excercise - Al '!J10<>""," SEND TO: "&'Excercise - Al '!J10,"") | F10: =IF('Excercise - Al '!K10<>"","STORYLINE: "&'Excercise - Al '!K10,"")&IF('Excercise - Al '!M10<>""," DESCRIPTION: "&'Excercise - Al '!M10,"")&IF('Excercise - Al '!O10<>""," NOTES/REMARKS: "&'Excercise - Al '!O10,"")&IF('Excercise - Al '!Q10<>""," BACKGROUND INFO: "&'Excercise - Al '!Q10,"") -> STORYLINE: Tropical Storm Al Update 5 DESCRIPTION: Tropical Storm Al Update 5 | G10: =IF('Excercise - Al '!P10<>"","IMPLEMENTER: "&'Excercise - Al '!P10,"") | H10: =IF('Excercise - Al '!N10<>"","EXPECTED ACTIONS: "&'Excercise - Al '!N10,"") | I10: ='Excercise - Al '!R10 -> Jenne
A11: ='Excercise - Al '!A11 -> 10 | C11: ='Excercise - Al '!E11 -> 40300.417 | D11: =IF('Excercise - Al '!F11<>0,'Excercise - Al '!F11,"") -> INFO | E11: =IF('Excercise - Al '!G11<>"","MODE: "&'Excercise - Al '!G11,"")&IF('Excercise - Al '!H11<>""," FROM: "&'Excercise - Al '!H11,"")&IF('Excercise - Al '!I11<>""," INJECTED BY: "&'Excercise - Al '!I11,"")&IF('Excercise - Al '!J11<>""," SEND TO: "&'Excercise - Al '!J11,"") -> MODE: Email FROM: Simcell - National Hurricane Center INJECTED BY: KEANE SEND TO: JOC, All | F11: =IF('Excercise - Al '!K11<>"","STORYLINE: "&'Excercise - Al '!K11,"")&IF('Excercise - Al '!M11<>""," DESCRIPTION: "&'Excercise - Al '!M11,"")&IF('Excercise - Al '!O11<>""," NOTES/REMARKS: "&'Excercise - Al '!O11,"")&IF('Excercise - Al '!Q11<>""," BACKGROUND INFO: "&'Excercise - Al '!Q11,"") -> STORYLINE: Tropical Storm Al Update 6 DESCRIPTION: Tropical Storm Al Update 6 | G11: =IF('Excercise - Al '!P11<>"","IMPLEMENTER: "&'Excercise - Al '!P11,"") -> IMPLEMENTER: ... HURRICANE AL TRACKS TOWARD THE YUCATAN... SUMMARY OF 1100 AM EDT...0900 UTC...INFORMATION ----------------------------------------------- LOCATION...16.3N 79.0W ABOUT 257 MILES... 321 KM...SOUTH SOUTHEAST OF GEORGE TOWN CAYMAN ISLANDS ABOUT 137 MILES... 222 KM...SOUTH OF NEGRIL JAMAICA MAXIMUM SUSTAINED WINDS...85 MPH...137 KM/HR PRESENT MOVEMENT...WNW OR 284 DEGREES AT 12 MPH...19 KM/HR MINIMUM CENTRAL PRESSURE...977 MB...28.85 INCHES | H11: =IF('Excercise - Al '!N11<>"","EXPECTED ACTIONS: "&'Excercise - Al '!N11,"") | I11: ='Excercise - Al '!R11 -> Keane
A12: ='Excercise - Al '!A12 -> 11 | C12: ='Excercise - Al '!E12 -> 40300.5 | D12: =IF('Excercise - Al '!F12<>0,'Excercise - Al '!F12,"") -> RFI | E12: =IF('Excercise - Al '!G12<>"","MODE: "&'Excercise - Al '!G12,"")&IF('Excercise - Al '!H12<>""," FROM: "&'Excercise - Al '!H12,"")&IF('Excercise - Al '!I12<>""," INJECTED BY: "&'Excercise - Al '!I12,"")&IF('Excercise - Al '!J12<>""," SEND TO: "&'Excercise - Al '!J12,"") -> MODE: Email FROM: Each Task Force INJECTED BY: TF S2 SEND TO: JOC, J2 | F12: =IF('Excercise - Al '!K12<>"","STORYLINE: "&'Excercise - Al '!K12,"")&IF('Excercise - Al '!M12<>""," DESCRIPTION: "&'Excercise - Al '!M12,"")&IF('Excercise - Al '!O12<>""," NOTES/REMARKS: "&'Excercise - Al '!O12,"")&IF('Excercise - Al '!Q12<>""," BACKGROUND INFO: "&'Excercise - Al '!Q12,"") -> DESCRIPTION: Weather Update/Storm Track | G12: =IF('Excercise - Al '!P12<>"","IMPLEMENTER: "&'Excercise - Al '!P12,"") -> IMPLEMENTER: Weather RFI from Task Force to J2 | H12: =IF('Excercise - Al '!N12<>"","EXPECTED ACTIONS: "&'Excercise - Al '!N12,"") -> EXPECTED ACTIONS: J2 Provides latest Weather and Storm Track to the TFs | I12: ='Excercise - Al '!R12 -> Houlton
A13: ='Excercise - Al '!A13 -> 12 | C13: ='Excercise - Al '!E13 -> 40300.667 | D13: =IF('Excercise - Al '!F13<>0,'Excercise - Al '!F13,"") -> INFO | E13: =IF('Excercise - Al '!G13<>"","MODE: "&'Excercise - Al '!G13,"")&IF('Excercise - Al '!H13<>""," FROM: "&'Excercise - Al '!H13,"")&IF('Excercise - Al '!I13<>""," INJECTED BY: "&'Excercise - Al '!I13,"")&IF('Excercise - Al '!J13<>""," SEND TO: "&'Excercise - Al '!J13,"") -> MODE: Email FROM: Simcell - National Hurricane Center INJECTED BY: KEANE SEND TO: JOC, All | F13: =IF('Excercise - Al '!K13<>"","STORYLINE: "&'Excercise - Al '!K13,"")&IF('Excercise - Al '!M13<>""," DESCRIPTION: "&'Excercise - Al '!M13,"")&IF('Excercise - Al '!O13<>""," NOTES/REMARKS: "&'Excercise - Al '!O13,"")&IF('Excercise - Al '!Q13<>""," BACKGROUND INFO: "&'Excercise - Al '!Q13,"") -> STORYLINE: Tropical Storm Al Update 7 DESCRIPTION: Tropical Storm Al Update 7 | G13: =IF('Excercise - Al '!P13<>"","IMPLEMENTER: "&'Excercise - Al '!P13,"") -> IMPLEMENTER: ... HURRICANE AL TRACKS TOWARD THE YUCATAN...AS A CATEGORY TWO HURRICANE... SUMMARY OF 0500 AM EDT...0900 UTC...INFORMATION ----------------------------------------------- LOCATION...16.7N 80.0W ABOUT 199 MILES... 321 KM...SOUTH SOUTHEAST OF GEORGE TOWN CAYMAN ISLANDS ABOUT 150 MILES... 241 KM...NEGRIL JAMAICA MAXIMUM SUSTAINED WINDS...105 MPH...169 KM/HR PRESENT MOVEMENT...WNW OR 292 DEGREES AT 12 MPH...19 KM/HR MINIMUM CENTRAL PRESSURE...968 MB...28.59 INCHES | H13: =IF('Excercise - Al '!N13<>"","EXPECTED ACTIONS: "&'Excercise - Al '!N13,"") | I13: ='Excercise - Al '!R13 -> Keane
A14: ='Excercise - Al '!A14 -> 13 | C14: ='Excercise - Al '!E14 -> 40300.917 | D14: =IF('Excercise - Al '!F14<>0,'Excercise - Al '!F14,"") -> INFO | E14: =IF('Excercise - Al '!G14<>"","MODE: "&'Excercise - Al '!G14,"")&IF('Excercise - Al '!H14<>""," FROM: "&'Excercise - Al '!H14,"")&IF('Excercise - Al '!I14<>""," INJECTED BY: "&'Excercise - Al '!I14,"")&IF('Excercise - Al '!J14<>""," SEND TO: "&'Excercise - Al '!J14,"") -> MODE: Email FROM: Simcell - National Hurricane Center INJECTED BY: KEANE SEND TO: JOC, All | F14: =IF('Excercise - Al '!K14<>"","STORYLINE: "&'Excercise - Al '!K14,"")&IF('Excercise - Al '!M14<>""," DESCRIPTION: "&'Excercise - Al '!M14,"")&IF('Excercise - Al '!O14<>""," NOTES/REMARKS: "&'Excercise - Al '!O14,"")&IF('Excercise - Al '!Q14<>""," BACKGROUND INFO: "&'Excercise - Al '!Q14,"") -> STORYLINE: Tropical Storm Al Update 8 DESCRIPTION: Tropical Storm Al Update 8 | G14: =IF('Excercise - Al '!P14<>"","IMPLEMENTER: "&'Excercise - Al '!P14,"") -> IMPLEMENTER: ... HURRICANE AL GAINS MOMENTUM AS A CATEGORY TWO HURRICANE... SUMMARY OF 2300 PM EDT...0300 UTC...INFORMATION ----------------------------------------------- LOCATION...17.1N 80.9W ABOUT 184 MILES...296 KM...WEST-SOUTHWEST NEGRIL JAMAICA ABOUT 154 MILES...249 KM...SOUTH-SOUTHEAST OF GEORGE TOWN CAYMAN ISLANDS MAXIMUM SUSTAINED WINDS...105 MPH...169 KM/HR PRESENT MOVEMENT...WNW OR 292 DEGREES AT 15 MPH...24 KM/HR MINIMUM CENTRAL PRESSURE...963 MB...28.44 INCHES | H14: =IF('Excercise - Al '!N14<>"","EXPECTED ACTIONS: "&'Excercise - Al '!N14,"") | I14: ='Excercise - Al '!R14 -> Keane
... A240: ='Excercise - Al '!A240 -> 239 | C240: ='Excercise - Al '!E240 -> 40304.75 | D240: =IF('Excercise - Al '!F240<>0,'Excercise - Al '!F240,"") | E240: =IF('Excercise - Al '!G240<>"","MODE: "&'Excercise - Al '!G240,"")&IF('Excercise - Al '!H240<>""," FROM: "&'Excercise - Al '!H240,"")&IF('Excercise - Al '!I240<>""," INJECTED BY: "&'Excercise - Al '!I240,"")&IF('Excercise - Al '!J240<>""," SEND TO: "&'Excercise - Al '!J240,"") | F240: =IF('Excercise - Al '!K240<>"","STORYLINE: "&'Excercise - Al '!K240,"")&IF('Excercise - Al '!M240<>""," DESCRIPTION: "&'Excercise - Al '!M240,"")&IF('Excercise - Al '!O240<>""," NOTES/REMARKS: "&'Excercise - Al '!O240,"")&IF('Excercise - Al '!Q240<>""," BACKGROUND INFO: "&'Excercise - Al '!Q240,"") -> STORYLINE: Transport food, water, and ice from LSA Brookley Field to LSA's located in Mobile and Baldwin Counties. Commodities to move are 400 Pallets of MRE, 500 Pallets of water, 100 Pallets of Ice, this will be a LOG Push mission daily. Mission duration is TBD. | G240: =IF('Excercise - Al '!P240<>"","IMPLEMENTER: "&'Excercise - Al '!P240,"") -> IMPLEMENTER: Transport food, water, and ice from LSA Brookley Field to LSA's located in Mobile and Baldwin Counties. Commodities to move are 400 Pallets of MRE, 500 Pallets of water, 100 Pallets of Ice, this will be a LOG Push mission daily. Mission duration is TBD. | H240: =IF('Excercise - Al '!N240<>"","EXPECTED ACTIONS: "&'Excercise - Al '!N240,"") | I240: ='Excercise - Al '!R240 -> 0
