Workbook
Name OLE_LINK1: 'Excercise - Al '!$P$59
Name OLE_LINK1: 'MSEL INFO ONLY'!$O$147

Sheet Excercise - Al 
A1: MSEL NUMBER | B1: DATE | C1: Time | D1: STATUS | E1: INJECT DTG | F1: SUBJECT | G1: INJECT MODE | H1: SEND FROM (Simulated) | I1: INJECTED BY | J1: SEND TO | K1: STORYLINE/THREAD | L1: ESF | M1: DESCRIPTION | N1: EXPECTED ACTION | O1: NOTES/REMARKS | P1: IMPLEMENTER (Actual Narrative) | Q1: BACKGROUND INFORMATION | R1: Inject Author
A2: 1 | D2: Omitted | E2: 40298.208 | F2: 31st CHEM BDE - Notifies select staff | G2: Not Injected | R2: Napier
A3: 2 | B3: 40299 | C3: 40299.167 | D3: Injected | E3: 40299.167 | F3: INFO | G3: Email | H3: Simcell - National Hurricane Center | I3: KEANE | J3: JOC, All | K3: Tropical Depression One Forms | L3: 5, 15 | M3: Tropical Depression One Forms | P3: On 01 May, 0400 HRS CDT, The National Hurricane Center issues Tropical Depression Advisory "One". Current Location 14.5 N 74.1 W Max Sustained Wind 30mph | R3: Keane
A4: 3 | D4: Omitted | E4: 40299.208 | F4: 31st CHEM BDE - Telecon with unit CDRs and issue verbal WARNO | G4: Not Injected | R4: Napier
A5: 4 | D5: Omitted | E5: 40299.208 | F5: 31st CHEM BDE - Test alert roster of key personnel and for the 1165th and 690th | G5: Not Injected | R5: Napier
A6: 5 | B6: 40299 | C6: 40299.417 | D6: Injected | E6: 40299.417 | F6: INFO | G6: Email | H6: Simcell - National Hurricane Center | I6: KEANE | J6: JOC, All | K6: Tropical Storm Al Update 2 | L6: 5, 15 | M6: Tropical Storm Al Update 2 | P6: ...FIRST TROPICAL STORM OF THE SEASON...AL NEARS THE COAST OF NICARAGUA... SUMMARY OF 1100 AM EDT...1500 UTC...INFORMATION ----------------------------------------------- LOCATION...14.9N 74.9W ABOUT 220 MILES...354 KM...SOUTH SOUTHEAST OF KINGSTON JAMAICA ABOUT 280 MILES...450 KM...NORTH OF BARRANQUILLA COLUMBIA ABOUT 510 MILES...820 KM...NORTHEAST OF PANAMA CITY PANAMA MAXIMUM SUSTAINED WINDS...45 MPH...39 KM/HR PRESENT MOVEMENT...WNW OR 276 DEGREES AT 15 MPH...24 KM/HR MINIMUM CENTRAL PRESSURE...999 MB...29.5 INCHES | R6: Keane
A7: 6 | B7: 40299 | C7: 40299.667 | D7: Injected | E7: 40299.667 | F7: INFO | G7: Email | H7: Simcell - National Hurricane Center | I7: KEANE | J7: JOC, All | K7: Tropical Storm Al Update 3 | L7: 5, 15 | M7: Tropical Storm Al Update 3 | P7: ...TROPICAL STORM AL STRENGTHENS AS IT NEARS THE COAST OF NICARAGUA... SUMMARY OF 1700 AM EDT...2100 UTC...INFORMATION ----------------------------------------------- LOCATION...15.30 N 76.20 W ABOUT 188 MILES...303 KM...167 DEGREES...SOUTH-SOUTHEAST OF KINGSTON JAMAICA ABOUT 312 MILES...502 KM...343 DEGREES...NORTH-NORTHWEST OF BARRANQUILLA COLUMBIA MAXIMUM SUSTAINED WINDS...60 MPH...99 KM/HR PRESENT MOVEMENT...WESTERLY OR 275 DEGREES AT 10 MPH...16 KM/HR MINIMUM CENTRAL PRESSURE...997 MB...29.44 INCHES | R7: Keane
A8: 7 | B8: 40299 | C8: 40299.917 | D8: Injected | E8: 40299.917 | F8: INFO | G8: Email | H8: Simcell - National Hurricane Center | I8: KEANE | J8: JOC, All | K8: Tropical Storm Al Update 4 | L8: 5, 15 | M8: Tropical Storm Al Update 4 | P8: ...AL BECOMES A HURRICANE AS IT NEARS THE NORTH COAST OF NICARAGUA... SUMMARY OF 1100 PM EDT...0300 UTC...INFORMATION ----------------------------------------------- LOCATION...15.50 N 77.10 W ABOUT 172 MILES...277 KM...SOUTH SOUTHEAST OF KINGSTON JAMAICA ABOUT 366 MILES...589 KM...NORTH-NORTHWEST OF CARTAGENA COLUMBIA MAXIMUM SUSTAINED WINDS...85 MPH...137 KM/HR PRESENT MOVEMENT...WNW OR 284 DEGREES AT 12 MPH...19 KM/HR MINIMUM CENTRAL PRESSURE...980 MB...28.94 INCHES | R8: Keane
A9: 8 | B9: 40300 | C9: 40300.167 | D9: Injected | E9: 40300.167 | F9: INFO | G9: Email | H9: Simcell - National Hurricane Center | I9: KEANE | J9: JOC, All | K9: Tropical Storm Al Update 4 | L9: 5, 15 | M9: Tropical Storm Al Update 4 | P9: ...AL REMAINS A CAT 1 HURRICANE MOVING EAST TO WEST...SOUTH OF JAMAICA...GAINING STRENGTH... SUMMARY OF 0500 AM EDT...0900 UTC...INFORMATION ----------------------------------------------- LOCATION...15.90 N 78.10 W ABOUT 159 MILES... 255 KM... SOUTH NEGRIL JAMAICA ABOUT 317 MILES... 510 KM... SOUTHEAST OF GEORGE TOWN CAYMAN ISLANDS ABOUT 375 MILES... 604 KM... EAST-NORTHEAST OF PUERTO CABEZAS NICARAGUA MAXIMUM SUSTAINED WINDS...85 MPH...137 KM/HR PRESENT MOVEMENT...WNW OR 282 DEGREES AT 12 MPH...19 KM/HR MINIMUM CENTRAL PRESSURE...979 MB...28.91 INCHES | R9: Keane
A10: 9 | B10: 40300.208 | C10: 40300.208 | D10: Injected | E10: 40300.208 | F10: INFO | K10: Tropical Storm Al Update 5 | M10: Tropical Storm Al Update 5 | R10: Jenne
A11: 10 | B11: 40300 | C11: 40300.417 | D11: Injected | E11: 40300.417 | F11: INFO | G11: Email | H11: Simcell - National Hurricane Center | I11: KEANE | J11: JOC, All | K11: Tropical Storm Al Update 6 | L11: 5, 15 | M11: Tropical Storm Al Update 6 | P11: ... HURRICANE AL TRACKS TOWARD THE YUCATAN... SUMMARY OF 1100 AM EDT...0900 UTC...INFORMATION ----------------------------------------------- LOCATION...16.3N 79.0W ABOUT 257 MILES... 321 KM...SOUTH SOUTHEAST OF GEORGE TOWN CAYMAN ISLANDS ABOUT 137 MILES... 222 KM...SOUTH OF NEGRIL JAMAICA MAXIMUM SUSTAINED WINDS...85 MPH...137 KM/HR PRESENT MOVEMENT...WNW OR 284 DEGREES AT 12 MPH...19 KM/HR MINIMUM CENTRAL PRESSURE...977 MB...28.85 INCHES | R11: Keane
A12: 11 | B12: 40300 | C12: 0.5 | D12: Injected | E12: 40300.5 | F12: RFI | G12: Email | H12: Each Task Force | I12: TF S2 | J12: JOC, J2 | M12: Weather Update/Storm Track | N12: J2 Provides latest Weather and Storm Track to the TFs | P12: Weather RFI from Task Force to J2 | R12: Houlton
A13: 12 | B13: 40300 | C13: 40300.667 | D13: Injected | E13: 40300.667 | F13: INFO | G13: Email | H13: Simcell - National Hurricane Center | I13: KEANE | J13: JOC, All | K13: Tropical Storm Al Update 7 | L13: 5, 15 | M13: Tropical Storm Al Update 7 | P13: ... HURRICANE AL TRACKS TOWARD THE YUCATAN...AS A CATEGORY TWO HURRICANE... SUMMARY OF 0500 AM EDT...0900 UTC...INFORMATION ----------------------------------------------- LOCATION...16.7N 80.0W ABOUT 199 MILES... 321 KM...SOUTH SOUTHEAST OF GEORGE TOWN CAYMAN ISLANDS ABOUT 150 MILES... 241 KM...NEGRIL JAMAICA MAXIMUM SUSTAINED WINDS...105 MPH...169 KM/HR PRESENT MOVEMENT...WNW OR 292 DEGREES AT 12 MPH...19 KM/HR MINIMUM CENTRAL PRESSURE...968 MB...28.59 INCHES | R13: Keane
A14: 13 | B14: 40300 | C14: 40300.917 | D14: Injected | E14: 40300.917 | F14: INFO | G14: Email | H14: Simcell - National Hurricane Center | I14: KEANE | J14: JOC, All | K14: Tropical Storm Al Update 8 | L14: 5, 15 | M14: Tropical Storm Al Update 8 | P14: ... HURRICANE AL GAINS MOMENTUM AS A CATEGORY TWO HURRICANE... SUMMARY OF 2300 PM EDT...0300 UTC...INFORMATION ----------------------------------------------- LOCATION...17.1N 80.9W ABOUT 184 MILES...296 KM...WEST-SOUTHWEST NEGRIL JAMAICA ABOUT 154 MILES...249 KM...SOUTH-SOUTHEAST OF GEORGE TOWN CAYMAN ISLANDS MAXIMUM SUSTAINED WINDS...105 MPH...169 KM/HR PRESENT MOVEMENT...WNW OR 292 DEGREES AT 15 MPH...24 KM/HR MINIMUM CENTRAL PRESSURE...963 MB...28.44 INCHES | R14: Keane
A15: 14 | B15: 40301 | C15: 40301.167 | D15: Injected | E15: 40301.167 | F15: INFO | G15: Email | H15: Simcell - National Hurricane Center | I15: KEANE | J15: JOC, All | K15: Tropical Storm Al Update 9 | L15: 5, 15 | M15: Tropical Storm Al Update 9 | P15: ... HURRICANE AL CONTINUES ON A TRACK TOWARD COZUMEL... SUMMARY OF 0500 AM EDT...0900 UTC...INFORMATION ----------------------------------------------- LOCATION...17.7N 82.1W ABOUT 250 MILES...401 KM...WEST-SOUTHWEST NEGRIL JAMAICA ABOUT 154 MILES...249 KM...SOUTH-SOUTHEAST OF GEORGE TOWN CAYMAN ISLANDS MAXIMUM SUSTAINED WINDS...105 MPH...169 KM/HR PRESENT MOVEMENT...WNW OR 294 DEGREES AT 14 MPH...23 KM/HR MINIMUM CENTRAL PRESSURE...960 MB...28.35 INCHES | R15: Keane
A16: 15 | D16: Omitted | E16: 40301.208 | F16: 31st CHEM BDE - Stands up the CAC and begins tracking storm | G16: Not Injected | R16: Napier
A17: 16 | D17: Omitted | E17: 40301.208 | F17: 31st CHEM BDE - Alert 1165th & 690th O/O Activate | G17: Not Injected | R17: Napier
A18: 17 | B18: 40301 | C18: 40301.292 | D18: Injected | E18: 40301.292 | F18: LNO to SEOC | G18: EMITS | H18: SEOC LNO | I18: SEOC LNO | J18: JOC | M18: NG LNO's to State EOC by 0700 4 May 10 | P18: NG LNO's to State EOC by 0700 4 May 10 | R18: Keane
A19: 18 | B19: 40301.312 | C19: 40301.312 | D19: Injected | E19: 40301.313 | F19: RFI - Holman Prison | G19: Phone Call | H19: JTF-S White Cell (subordinnate commander) | I19: TOMBERLIN | J19: 226 MEB | K19: Holman Prison Blues | M19: Company commander requests guidance on soldier | O19: Inject called in on schedule. Monitoring of JOC message traffic indicates that information apparently did not make it outside of 226 MEB. | P19: Company commander has a soldier who is a prison guard at Holman Prison. Soldier states that he has been directed to remain at prison and not to report to Guard. Indicates rumors of potential inmate takeover and mass escape during hurricane. Soldier/guard states that inmates are apparently planning a takeover while hurricane is in progress, followed by mass escape. There are indications that they may receive external support by an affilated gang. Soldier/guard states that prison officials are discussing requesting security assistance from Guard. | R19: Jenne
A20: 19 | D20: Injected | E20: 40301.314 | F20: MISSION | G20: EMITS | H20: AEMA ESF 5 | I20: SEOC LNO | J20: JOC | L20: 5 | M20: Provide meteorological services to SEOC (AL) | P20: Provide meteorological services to SEOC (AL) | R20: Keane
A21: 20 | D21: Injected | E21: 40301.333 | F21: AEMA Contacts JOC | G21: Phone | H21: AEMA | I21: ALAN PETTY | J21: AL J3 | M21: AEMA Director contacts AL TAG/J3 to discuss hurricane response planning/operations. | P21: AEMA Director contacts AL TAG/J3 to discuss hurricane response planning/operations. AEMA Director states that they are making preliminary plans for possible Alex response operations. Suggests issuing warning orders to MACOMs for potential in-state response operations. | R21: Keane
A22: 21 | B22: 40301 | C22: 0.33333333 | D22: Injected | E22: 40301.335 | F22: MISSION - SASO | G22: Email | H22: simcell-SEOC | I22: SEOC LNO | J22: J35 | K22: SASO | M22: SASO Request | N22: EOC contacts 122CSG | P22: Email Emits message' AEMA SEOC Request ALNG Provide SASO to MAFB | R22: Messer
A23: 22 | B23: 40301 | C23: 0.33333333 | D23: Injected | E23: 40301.335 | F23: MISSION - SEOC LOG CELL | G23: Email | H23: simcell-SEOC | I23: SEOC LNO | J23: J35 | K23: SEOC Log Cell | M23: SEOC Log Cell Request | N23: EOC contacts 122CSG | P23: Email Emits message' AEMA SEOC Request ALNG Provide SEOC Log Cell to Clanton Al. | R23: Messer
A24: 23 | B24: 40301 | C24: 0.35416667 | D24: Deferred | E24: 40301.354 | F24: INFO | G24: Phone | H24: simcell-citizen | I24: HOWARD | J24: Message Center | K24: MVC/ Fatality | M24: Report of Accident | N24: EOC RFIs MACOMS regarding report of accident/vehicles on road | P24: Citizen: I am a retired ARNG member and I just say one of your Humvee's run a stop sign and hit a mini van, and flipped it and it ran off the road. I didn't see anyone get out of either vehicle. I have called 911, just thought you guys wanted to know. | R24: Messer
A25: 24 | D25: Injected | E25: 40301.376 | F25: INFO | G25: Email | H25: JIEE | I25: KAHL | J25: JOC | K25: Set NGB Conference call up on DCO | R25: Kahl
A26: 25 | B26: 40301 | C26: 0.375 | D26: Injected | E26: 40301.376 | F26: INFO | G26: Phone | H26: simcell_LNO | I26: SEOC LNO | J26: J35 | K26: Contra Flow | M26: Informal message from LNO | N26: WARNO to 62nd Troop Command | P26: I just heard that the Governor is probably going to order contra flow on I 65 sometimes tomorrow morning. I will let you know more as I hear it. | R26: Messer
A27: 26 | D27: Injected | E27: 40301.377 | F27: INFO | G27: Email | H27: NGB | I27: KAHL | J27: JOC | K27: Set up event and Share with NGB | R27: Kahl
A28: 27 | D28: Injected | E28: 40301.378 | F28: RFI | G28: JIEE | H28: JIEE | I28: KAHL | J28: JOC | K28: Does the JOC need a JET or PARRT | M28: Request for JET | R28: Kahl
A29: 28 | B29: 40301 | D29: Injected | E29: 40301.378 | F29: INFO | I29: SEOC LNO | M29: The State Emergency Response Team (SERT) is recalled to the State Emergency Operations Center (SEOC (AL)) and activated at Level 1 effective 0900 3 May 2010. | P29: The State Emergency Response Team (SERT) is recalled to the State Emergency Operations Center (SEOC (AL)) and activated at Level 1 effective 0900 3 May 2010. | R29: Keane
A30: 29 | B30: 40301 | C30: 40301.375 | D30: Injected | E30: 40301.379 | F30: MISSION | G30: Email | H30: USPFO, S&S | I30: DENNIS | J30: JOC J4 | M30: USPFO Warehouse to push 20 pallets of MREs and 20 pallets of bottled water to Ft McClellan, AL (pre-positioning for soldier support). | P30: USPFO Warehouse to push 20 pallets of MREs and 20 pallets of bottled water to Ft McClellan, AL (pre-positioning for soldier support). | Q30: USPFO Warehouse SOP, SA only | R30: Keane
A31: 30 | B31: 40301 | D31: Injected | E31: 40301.381 | F31: INFO - Evacuation | I31: SEOC LNO | M31: AEMA recommends voluntary evacuation of Baldwin and Mobile counties. | P31: AEMA recommends voluntary evacuation of Baldwin and Mobile counties. Voluntary evacuations recommended for citizens living in mobile homes for the following counties: Washington, Clarke, Monroe, Conecuh, Escambia, Covington, Geneva, and Houston. | R31: Keane
A32: 31 | B32: 40301 | D32: Injected | E32: 40301.381 | F32: INFO | I32: KEANE | M32: JFHQ activates JTF-South (FTUS) Primary Staff (LNO's)and local units for possible support | P32: JFHQ activates JTF-South (FTUS) Primary Staff (LNO's)and local units for possible support | R32: Keane
A33: 32 | D33: Injected | E33: 40301.385 | F33: INFO | G33: Email | H33: MED DET | I33: BENTON | J33: SPS MED & J1 | K33: 1 Soldier found HIV positive in the 226th MEB after a periodic health assessment (PHA) performed by the medical detachment, from 10-11 Apr 10 SRP in Mobile. | M33: 1 Soldier found HIV positive in the 226th MEB after a periodic health assessment (PHA) performed by the medical detachment, from 10-11 Apr 10 SRP in Mobile. | P33: 1 Soldier found HIV positive in the 226th MEB after a periodic health assessment (PHA) performed by the medical detachment, from 10-11 Apr 10 SRP in Mobile. | R33: Benton
A34: 33 | D34: Injected | E34: 40301.385 | I34: P. MCDONALD | J34: JOC MSG CTR | K34: Army National Guard CAT requests Alabama review resources available IOT support FL with 1X Med Trk Co and 1X DS/GS Maint Co. | O34: At 0939 hours LTC Small , ARNG CAT, contacted MAJ Davis @ 334.273.3547 after several attempts to other numbers provided by SGT Vice. He is to advise. At 1114 hours, MAJ Davis advises TAG-AL requests a 48 hour hold before approving the EMAC request. | P34: Army National Guard CAT requests Alabama review resources available IOT support FL with 1X Med Trk Co and 1X DS/GS Maint Co. | R34: McDonald
A35: 34 | D35: Injected | E35: 40301.386 | F35: INFO | G35: Telephone Call | H35: STATE SURGEON | I35: BENTON | J35: SPS MED | K35: All JTFs must perform a medical readiness screening of the potential personnel being considered for DSCA support mission to ensure that they have a current PHA, Dental Exam, Routine Adult Immunizations (to include H1N1) and have no outstanding noon-deployable medical conditions. Submit status report back to SPS.MED NLT 1200 4 May 10. | M35: All JTFs must perform a medical readiness screening of the potential personnel being considered for DSCA support mission to ensure that they have a current PHA, Dental Exam, Routine Adult Immunizations (to include H1N1) and have no outstanding noon-deployable medical conditions. Submit status report back to SPS.MED NLT 1200 4 May 10. | P35: All JTFs must perform a medical readiness screening of the potential personnel being considered for DSCA support mission to ensure that they have a current PHA, Dental Exam, Routine Adult Immunizations (to include H1N1) and have no outstanding noon-deployable medical conditions. Submit status report back to SPS.MED NLT 1200 4 May 10. | R35: Benton
A36: 35 | B36: 40301 | D36: Injected | E36: 40301.387 | F36: INFO | I36: SEOC LNO | M36: TF South gets notification of pending activation | P36: TF South gets notification of pending activation | R36: Keane
A37: 36 | D37: Injected | E37: 40301.389 | I37: P. MCDONALD | K37: Army National Guard CAT requests Alabama review resources available IOT support TX with 1x Light/Medium Truck Company and 1x POL Co. | O37: At 0923 hours LTC Small, ARNG CAT, contacted MSG Woodall @ 334.213.7748 and he took message and would have someone return our call. At 1007 hours called MSG Woodall and advised no one had called. Left another message. At 1114 hours MAJ Davis, AL JOC returned call and received request. Will advise. At 1715 hours, MAJ Davis advises TAG will concur with request but requests a 48 hours delay for the EMAC request. | P37: Army National Guard CAT requests Alabama review resources available IOT support TX with 1x Light/Medium Truck Company and 1x POL Co. | R37: McDonald
A38: 37 | B38: 40301 | D38: Injected | E38: 40301.39 | F38: INFO | I38: SEOC LNO | M38: FEMA Region JFO ERT-A will deploy to AEMA on 4 May about 1200, FEMA Region 9 DCO will serve as JFO-AL DCO | P38: FEMA Region JFO ERT-A will deploy to AEMA on 4 May about 1200, FEMA Region 9 DCO will serve as JFO-AL DCO | R38: Keane
A39: 38 | B39: 40301 | D39: Injected | E39: 40301.39 | F39: MISSION | I39: SEOC LNO | M39: Deploy SERT (AL) LNOs to Mobile and Baldwin counties NLT 4 May 1800. | P39: Deploy SERT (AL)LNOs to Mobile and Baldwin counties NLT 4 May 1800. | R39: Keane
A40: 39 | D40: Omitted | E40: 40301.392 | K40: Army National Guard CAT requests Alabama review resources available IOT support Tx and LA with unfilled EMAC Requests. | P40: Army National Guard CAT requests Alabama review resources available IOT support Tx and LA with unfilled EMAC Requests.
...

Sheet MSEL INFO ONLY
A1: MSEL NUMBER | B1: DATE | C1: Time | D1: INJECT DTG | E1: SUBJECT | F1: INJECT MODE | G1: SEND FROM (Simulated) | H1: INJECTED BY | I1: SEND TO | J1: STORYLINE/THREAD | K1: ESF | L1: DESCRIPTION | M1: EXPECTED ACTION | N1: NOTES/REMARKS | O1: IMPLEMENTER (Actual Narrative) | P1: BACKGROUND INFORMATION | Q1: Inject Author
B2: 40298.208 | C2: 40298.208 | D2: 40298.208 | E2: INFO | F2: Not Injected - MSEL Planning Info only | J2: Background Information (Hurricane Synchronization Matrix) | L2: 187 FW - Assemble EOC/Review CEMP 10-2, Annex B | Q2: Jenne
B3: 40298.208 | C3: 40298.208 | D3: 40298.209 | E3: INFO | F3: Not Injected - MSEL Planning Info only | J3: Background Information (Hurricane Synchronization Matrix) | L3: 20 SF - ID JOC LNO | Q3: Jenne
B4: 40298.208 | C4: 40298.208 | D4: 40298.21 | E4: INFO | F4: Not Injected - MSEL Planning Info only | J4: Background Information (Hurricane Synchronization Matrix) | L4: 62 TC - FTUS Hurricane Tracking, Initial PERSTAT and Logistics Capabilities PLACE SUB UNITS on REDCON 4 | Q4: Jenne
B5: 40298.208 | C5: 40298.208 | D5: 40298.21 | E5: INFO | F5: Not Injected - MSEL Planning Info only | J5: Background Information (Hurricane Synchronization Matrix) | L5: EOC/JOC - Assume Adaptive Battle Staff (ABS) 4; Submit Updated AL Capabilites Slide to NGB; place units on REDCON 4 | Q5: Jenne
B6: 40298.208 | C6: 40298.208 | D6: 40298.211 | E6: INFO | F6: Not Injected - MSEL Planning Info only | J6: Background Information (Hurricane Synchronization Matrix) | L6: J-1 / Family Readiness - Contact FRG Coordinators down range | Q6: Jenne
B7: 40298.208 | C7: 40298.208 | D7: 40298.212 | E7: INFO | F7: Not Injected - MSEL Planning Info only | J7: Background Information (Hurricane Synchronization Matrix) | L7: J-1 / Medical - Review CLS Qualifed Personnel | Q7: Jenne
B8: 40298.208 | C8: 40298.208 | D8: 40298.213 | E8: INFO | F8: Not Injected - MSEL Planning Info only | J8: Background Information (Hurricane Synchronization Matrix) | L8: J-1 / Safety - Begin statewide push on Hurricane and Tornado | Q8: Jenne
B9: 40298.208 | C9: 40298.208 | D9: 40298.213 | E9: INFO | F9: Not Injected - MSEL Planning Info only | J9: Background Information (Hurricane Synchronization Matrix) | L9: J-1 / Strength - Review J-1 / Medical, Avn/Trans, EN, MP, LG and SIG/IT Personnel Assets | Q9: Jenne
B10: 40298.208 | C10: 40298.208 | D10: 40298.214 | E10: INFO | F10: Not Injected - MSEL Planning Info only | J10: Background Information (Hurricane Synchronization Matrix) | L10: J-4 / Class I - Review MRE DOS, ensure sufficient 2 DOS per JTF | Q10: Jenne
B11: 40298.208 | C11: 40298.208 | D11: 40298.215 | E11: INFO | F11: Not Injected - MSEL Planning Info only | J11: Background Information (Hurricane Synchronization Matrix) | L11: J-4 / Class III - Link up with SPDOF and verify that fuel contracts listed are valid | Q11: Jenne
B12: 40298.208 | C12: 40298.208 | D12: 40298.215 | E12: INFO | F12: Not Injected - MSEL Planning Info only | J12: Background Information (Hurricane Synchronization Matrix) | L12: J-4 / Class IX - Verify status of CL IX push package. Verify maint status of equipement | Q12: Jenne
B13: 40298.208 | C13: 40298.208 | D13: 40298.216 | E13: INFO | F13: Not Injected - MSEL Planning Info only | J13: Background Information (Hurricane Synchronization Matrix) | L13: J-4 / Class V - Review requirements with FMARNGTC ATP. Verify sufficient on hand | Q13: Jenne
... B19: 40298.208 | C19: 40298.208 | D19: 40298.22 | E19: INFO | F19: Not Injected - MSEL Planning Info only | J19: Background Information (Hurricane Synchronization Matrix) | L19: JTF-S/226 MEB - FTUS Hurricane Tracking | Q19: Jenne
B20: 40299 | C20: 40299.167 | D20: 40299.167 | E20: INFO | F20: Email | G20: Simcell - National Hurricane Center | H20: Keane | I20: JOC, All | J20: Tropical Depression One Forms | K20: 5, 15 | L20: Tropical Depression One Forms | O20: On 01 May, 0400 HRS CDT, The National Hurricane Center issues Tropical Depression Advisory "One". Current Location 14.5 N 74.1 W Max Sustained Wind 30mph | Q20: Keane
B21: 40299.208 | C21: 40299.208 | D21: 40299.208 | E21: INFO | F21: Not Injected - MSEL Planning Info only | J21: Background Information (Hurricane Synchronization Matrix) | L21: 117 ARW - Inventory DR assets | Q21: Jenne
B22: 40299.208 | C22: 40299.208 | D22: 40299.209 | E22: INFO | F22: Not Injected - MSEL Planning Info only | J22: Background Information (Hurricane Synchronization Matrix) | L22: 187 FW - Inventory DR assets/Prepare to respond to JOC tasking | Q22: Jenne
B23: 40299.208 | C23: 40299.208 | D23: 40299.21 | E23: INFO | F23: Not Injected - MSEL Planning Info only | J23: Background Information (Hurricane Synchronization Matrix) | L23: 20 SF - Place SAR Tm on Alert, ID additional 20th Volunteers, Pre-Mission Checks on J-4 / Transportation and critical log | Q23: Jenne
B24: 40299.208 | C24: 40299.208 | D24: 40299.21 | E24: INFO | F24: Not Injected - MSEL Planning Info only | J24: Background Information (Hurricane Synchronization Matrix) | L24: 62 TC - Telecon with Unit Commanders, Issue verbal WARN ORDER | Q24: Jenne
B25: 40299.208 | C25: 40299.208 | D25: 40299.211 | E25: INFO | F25: Not Injected - MSEL Planning Info only | J25: Background Information (Hurricane Synchronization Matrix) | L25: EOC/JOC - Place units on REDCON 3 BPT activate FOSA at MAFB | Q25: Jenne
B26: 40299.208 | C26: 40299.208 | D26: 40299.212 | E26: INFO | F26: Not Injected - MSEL Planning Info only | J26: Background Information (Hurricane Synchronization Matrix) | L26: J-1 / Medical - Review Out of State Personnel Assets | Q26: Jenne
B27: 40299.208 | C27: 40299.208 | D27: 40299.213 | E27: INFO | F27: Not Injected - MSEL Planning Info only | J27: Background Information (Hurricane Synchronization Matrix) | L27: J-1 / Strength - Review Out of State Personnel Assets | Q27: Jenne
B28: 40299.208 | C28: 40299.208 | D28: 40299.213 | E28: INFO | F28: Not Injected - MSEL Planning Info only | J28: Background Information (Hurricane Synchronization Matrix) | L28: J-4 / Class IX - Continue to take necessary action to bring DSCA centric equipment to FMC | Q28: Jenne
B29: 40299.208 | C29: 40299.208 | D29: 40299.214 | E29: INFO | F29: Not Injected - MSEL Planning Info only | J29: Background Information (Hurricane Synchronization Matrix) | L29: JTF-S/226 MEB - Advise TF Units of REDCON 3 Status | Q29: Jenne
B30: 40299.208 | C30: 40299.208 | D30: 40299.215 | E30: INFO | F30: Not Injected - MSEL Planning Info only | J30: Background Information (Hurricane Synchronization Matrix) | L30: JTF-S/226 MEB - Assumes REDCON 4 and prepares to execute JFHQ OPLAN 10-200. | Q30: Jenne
B31: 40299.208 | C31: 40299.208 | D31: 40299.215 | E31: INFO | F31: Not Injected - MSEL Planning Info only | J31: Background Information (Hurricane Synchronization Matrix) | L31: JTF-S/226 MEB - Begin initial preparation for standing up JTF-S staff and the IEF. | Q31: Jenne
B32: 40299.208 | C32: 40299.208 | D32: 40299.216 | E32: INFO | F32: Not Injected - MSEL Planning Info only | J32: Background Information (Hurricane Synchronization Matrix) | L32: JTF-S/226 MEB - Establish communications with Baldwin and Mobile Counties | Q32: Jenne
... B34: 40299.208 | C34: 40299.208 | D34: 40299.217 | E34: INFO | F34: Not Injected - MSEL Planning Info only | J34: Background Information (Hurricane Synchronization Matrix) | L34: JTF-S/226 MEB - Test alert roster for key personnel TPFDD to JTF-S | Q34: Jenne
B35: 40299 | C35: 40299.417 | D35: 40299.417 | E35: INFO | F35: Email | G35: Simcell - National Hurricane Center | H35: Keane | I35: JOC, All | J35: Tropical Storm Al Update 2 | K35: 5, 15 | L35: Tropical Storm Al Update 2 | O35: ...FIRST TROPICAL STORM OF THE SEASON...AL NEARS THE COAST OF NICARAGUA... SUMMARY OF 1100 AM EDT...1500 UTC...INFORMATION ----------------------------------------------- LOCATION...14.9N 74.9W ABOUT 220 MILES...354 KM...SOUTH SOUTHEAST OF KINGSTON JAMA | Q35: Keane
B36: 40299 | C36: 40299.667 | D36: 40299.667 | E36: INFO | F36: Email | G36: Simcell - National Hurricane Center | H36: Keane | I36: JOC, All | J36: Tropical Storm Al Update 3 | K36: 5, 15 | L36: Tropical Storm Al Update 3 | O36: ...TROPICAL STORM AL STRENGTHENS AS IT NEARS THE COAST OF NICARAGUA... SUMMARY OF 1700 AM EDT...2100 UTC...INFORMATION ----------------------------------------------- LOCATION...15.30 N 76.20 W ABOUT 188 MILES...303 KM...167 DEGREES...SOUTH-SOUTHEAST OF | Q36: Keane
B37: 40299 | C37: 40299.917 | D37: 40299.917 | E37: INFO | F37: Email | G37: Simcell - National Hurricane Center | I37: JOC, All | J37: Tropical Storm Al Update 4 | K37: 5, 15 | L37: Tropical Storm Al Update 4 | O37: ...AL BECOMES A HURRICANE AS IT NEARS THE NORTH COAST OF NICARAGUA... SUMMARY OF 1100 PM EDT...0300 UTC...INFORMATION ----------------------------------------------- LOCATION...15.50 N 77.10 W ABOUT 172 MILES...277 KM...SOUTH SOUTHEAST OF KINGSTON JAMAI | Q37: Keane
B38: 40300 | C38: 40300.167 | D38: 40300.167 | E38: INFO | F38: Email | G38: Simcell - National Hurricane Center | H38: Keane | I38: JOC, All | J38: Tropical Storm Al Update 4 | K38: 5, 15 | L38: Tropical Storm Al Update 4 | O38: ...AL REMAINS A CAT 1 HURRICANE MOVING EAST TO WEST...SOUTH OF JAMAICA...GAINING STRENGTH... SUMMARY OF 0500 AM EDT...0900 UTC...INFORMATION ----------------------------------------------- LOCATION...15.90 N 78.10 W ABOUT 159 MILES... 255 KM... SOUTH NE | Q38: Keane
B39: 40300.208 | C39: 40300.208 | D39: 40300.208 | E39: INFO | F39: Not Injected - MSEL Planning Info only | J39: Tropical Storm Al Update 5 | L39: Tropical Storm Al Update 5 | Q39: Jenne
B40: 40300.208 | C40: 40300.208 | D40: 40300.209 | E40: INFO | F40: Not Injected - MSEL Planning Info only | J40: Background Information (Hurricane Synchronization Matrix) | L40: 167 TSC - Issue BPT deploy order to 122d ASG and alert LNOs | Q40: Jenne
B41: 40300.208 | C41: 40300.208 | D41: 40300.21 | E41: INFO | F41: Not Injected - MSEL Planning Info only | J41: Background Information (Hurricane Synchronization Matrix) | L41: 187 FW - Implement CEMP 10-2 Annex B | Q41: Jenne
B42: 40300.208 | C42: 40300.208 | D42: 40300.21 | E42: INFO | F42: Not Injected - MSEL Planning Info only | J42: Background Information (Hurricane Synchronization Matrix) | L42: 20 SF - Dispatch LNO to State JOC, Cooridnate with 131st AVN | Q42: Jenne
B43: 40300.208 | C43: 40300.208 | D43: 40300.211 | E43: INFO | F43: Not Injected - MSEL Planning Info only | J43: Background Information (Hurricane Synchronization Matrix) | L43: 62 TC - Issue WARN ORDER 1, CMC Prep | Q43: Jenne
B44: 40300.208 | C44: 40300.208 | D44: 40300.212 | E44: INFO | F44: Not Injected - MSEL Planning Info only | J44: Background Information (Hurricane Synchronization Matrix) | L44: AEMA SEOC - Alert Alabama Mutual Aid System and County Liaisons | Q44: Jenne
B45: 40300.208 | C45: 40300.208 | D45: 40300.213 | E45: INFO | F45: Not Injected - MSEL Planning Info only | J45: Background Information (Hurricane Synchronization Matrix) | L45: AEMA SEOC -Activate Logistics Staging at Maxwell AFB | Q45: Jenne
B46: 40300.208 | C46: 40300.208 | D46: 40300.213 | E46: INFO | F46: Not Injected - MSEL Planning Info only | J46: Background Information (Hurricane Synchronization Matrix) | L46: AEMA SEOC -Activate Resource Contracts for Security, Food, Ice and Water | Q46: Jenne
...

Sheet Venue Fail Safe
A1: Hurricane Scenario
A2: Master Scenario Events List (MSEL)
A3: MSEL NUMBER | B3: DATE | C3: INJECT DTG | D3: SUBJECT | E3: INJECT MODE | F3: SEND FROM (Simulated) | G3: INJECTED BY | H3: SEND TO | I3: STORYLINE/THREAD | J3: ESF | K3: DESCRIPTION | L3: EXPECTED ACTION | M3: NOTES/REMARKS | N3: IMPLEMENTER (Actual Narrative) | O3: BACKGROUND INFORMATION | P3: Inject Author
A4: FS-1 | B4: 40301 | C4: 5/3/10 0715 | D4: NGB ABS Standup | E4: E-Mail | F4: NGB | G4: Huddleston | H4: ALNG JOC | I4: NGB JoCC has established ABS Level 2 in response to Hurricane AL | K4: NGB JoCC has established ABS Level 2 in response to Hurricane AL | L4: None | N4: Exercise Exercise Exercise | P4: Huddleston
A5: FS-2 | B5: 40301 | C5: 1015 | D5: NGB JoCC Requesting Hurricane States update Hurrican Matrices | E5: JIEE | F5: NGB-JoCC | G5: Huddleston | H5: All States | I5: NGB JoCC request all supported and supporting Hurricane State update their Hurricane Matrices ASAP and Provide to NGB JoCC, NLT 1400 EDT. | K5: NGB JoCC request all supported and supporting Hurricane State update their Hurricane Matrices ASAP and Provide to NGB JoCC, NLT 1400 EDT. | L5: AL JOC update their Hurricane Matrices | N5: NGB JoCC request all supported and supporting Hurricane State update their Hurricane Matrices ASAP and Provide to NGB JoCC, NLT 1400 EDT. | P5: Huddleston
A6: FS-3 | B6: 40301 | C6: 1900 | D6: RFI for Update of mission status | E6: JIEE | F6: NGB JoCC | G6: Huddleston | H6: AL JoCC | I6: The Gulf States in the potential path of Hurricane Al should keep NGB aprised of certain information but are not. | K6: The Gulf States in the potential path of Hurricane Al should keep NGB aprised of certain information | N6: As a result of Hurrican Al, the National Guard Bureau Adaptive Battle staff has been established at ABS Level 2 as of 0700 EDT, 3 May 2010. NGB Point of Contact for AL HURREX, Hurricane AL is, COL Sanders, 571-606-2396.
A7: FS-4 | B7: 40302 | C7: 930 | D7: Forklift request capable of handling L-463 pallets | E7: Telephone call, follow-up email JOC | F7: White Cell J4 | G7: McDonald | H7: J4 (telephone), email J33 | I7: Supplies are beginning to stock pile as they arrived at Mobile Regional Airport. The Airfield Manager indicated shipment after shipment are waiting to be off loaded as air cargo arrived. The only forklift presently located at Mobile regional Airport, which is capable of Handling L-463 pallets is not functioning. | L7: States ability to transport a forklift capable of handling L-463 pallets. NG ability to identify which unit MTOE has Line # T-49119 | N7: As a result of a malfunction forklift, Airfield Manager is requesting two 10,000lbs forklift capable of Handling L-463 pallets. POC whitecell J4, 4731
A8: FS-5 | B8: 40302 | C8: 1055 | D8: 1165th MP CO down vehicle | E8: Telephone call, follow-up email JOC | F8: White Cell TFAL | G8: Napier | H8: 31st Chem Bde | I8: While in route to report to JTF-S 1165th had a HMMWV's rear axle went out and is blocking one lane on Bay Bridge. 1165th does not have a tow bar or wrecker with the convoy. The company has left two soldiers with the vehicle and the rest of the company went to Fort Whiting. The traffic on Bay Bridge is backing up. | L8: 31st Chem Bde to JTF-S for support to assist with the down HMMWV
A9: FS-6 | B9: 40302 | C9: 1400 | D9: Engineers Batteries | E9: email | F9: White cell J-4 | G9: Cannon | H9: J-4 | I9: Engineers task to remove debris from roadway has equipment with dead batteries. Unit need 30ea of NSN 6140-01-493-1962, supporting FMS has zero on-hand. | L9: Expect purchase to be on Impac Card. Ensure J4 follows Impac procedures. | N9: NGB JoCC
A10: FS-7 | B10: 40302 | C10: 1730 | D10: Recovery Mission | E10: e-mail | F10: White cell J-4 | G10: Cannon, McDonald | H10: J-4 | I10: Accident on I-65 aand I-85 interchange involving 2 military LMTV's at 1715 hrs, request recovery mission, owning unit has no recovery capability | L10: Determine capability to task appropriate unit | N10: COL Sanders
N11: 571-606-2396
N12: exercise.ngb.jocc@gmail.com
N14: Exercise Exercise Exercise
A15: FS-8 | B15: 40303 | C15: 900 | D15: Network Problems | E15: Cell Phone Call | F15: FTUS NCO manning Citronelle Armory | G15: CW2 Snider | H15: JTF-South | I15: Citronelle Network Problems | K15: Question Concerning Network | L15: JTF South contact JFHQ-JOC. JFHQ-JOC contact J-6. | N15: I was walking down the hall and noticed that water was coming out from under the door of the telecom room. I opened the door and noticed that water is leaking from the roof all over the equipment that is in there. | O15: J6 should be involved for solution. | P15: Snider
A16: FS-9 | B16: 40303 | C16: 930 | D16: Students return to school | E16: e-mail | F16: white cell 1 | G16: MAJ Johnson | H16: jfhqal.j33.msg1 | I16: Troy University called and stated that SPC Mitchell and PFC Howard, with JTF South, need to return to class on Thursday. | L16: Message center contact JTF-S and J1 in order to take action. Action will affect Pay and will require communication and a plan to get these soldiers back to their HS. | N16: Troy University called and stated that SPC Mitchell and PFC Howard, with JTF South, need to return to class on Thursday. | P16: Johnson
A17: FS-10 | B17: 40303 | C17: 1130 | D17: Unknown individual shows up in uniform. Request to assist in mission. | E17: e-mail | F17: white cell 1 | G17: MAJ Johnson | H17: jfhqal.j33.msg1 | I17: JTF-South reports individual showed up in uniform stating he is a member of 31st Chem Brigade. No soldier with that name or SSN is on a Battle Roster or in SIDPERS. Individual insist on helping and states he will go to Civilian Reporters if rejected. Request guidance. | L17: Message center contact J1/JAG/PAO in order to take action. Action will require interaction with Civilian Authorities in the area of JTF-S and will require communication and a plan to remove individual from AO. | N17: JTF-South reports individual showed up in uniform stating he is a member of 31st Chem Brigade. No soldier with that name or SSN is on a Battle Roster or in SIDPERS. Individual insist on helping and states he will go to Civilian Reporters if rejected. Request guidance. | P17: Johnson
A18: FS-11 | B18: 40303 | C18: 1300 | D18: Soldier's wife going into labor and demanding that soldier be allowed to meet her at the hospital. | E18: e-mail | F18: white cell 1 | G18: MAJ Johnson | H18: jfhqal.j33.msg1 | I18: Red Cross states MAJ Sawyer's wife is going into labor at Sacred Heart in Pensacola. She is frantic and demands his presence. | L18: Message center contacts J1 in order to take action. Action will require interaction with J1 and soldier's unit. | N18: Red Cross states MAJ Sawyer's wife is going into labor at Sacred Heart in Pensacola. She is frantic and demands his presence. | P18: Johnson
A19: FS-12 | B19: 40303 | C19: 1020 | D19: A M916 hauling a MW24C 2 1/2 Yard Scooper Loader overturn I-10 | E19: email | F19: white cell 4 | G19: McDonald/Canno | H19: jfhqal.j33.msg1 | I19: M916 hauling a MW24C 2 1/2 Yard Scooper Loader convoying east on I-10 in Mobile, braking action cause tie down to break, which in turn, let the loader fall off the trailer, backing tracffic east bound. | L19: Heavy equipment Recovery procedure | N19: TF-South Dispacted Wrecker
A20: FS-13 | B20: 40303 | C20: 1300 | D20: Grove Hill - Jackson City Emergency Manager requested evacuation assistance from NG | E20: email | F20: white cell 4 | G20: McDonald/Canno | H20: State EMA | I20: Grove Hill - Jackson City area EM, requested assistance from ALNG to evacuation of 20 elderly personnel from the city of Jackson, relocating to B'Ham until Hurricrane had cleared. | L20: ALT Route procedure when main route is closed
A21: FS-14 | B21: 40301 | C21: 030932MAY10 | D21: Medical Readiness Status Update | E21: Telephone Call | F21: State Surgeon | G21: White Cell - Medical (MAJ Benton) | H21: J33 Message Center | I21: DTG (3029MAY2010) TELEPHONE CALL FROM STATE SURGEON: All JTFs need to screen all potential personnel to be activated for DSCA support missions to ensure that they have a current periodic health assessment (PHA), current dental examination, current on Routine Adult Immunizations (to include H1N1 Influenza) and have no outstanding non-deployable medical conditions. Status report needs to be submitted back to JFHQ-MED NLT 1200 4 May 10 in order to establish any follow on PHA, Dental and/or immunization mission requirements. | L21: JTFs to scrub potential personnel rosters and identify any shortfalls that the JFHQAL could establish missions to support. | M21: CLOSED | P21: BENTON
A22: FS-15 | B22: 40302 | C22: 041730MAY10 | D22: CL VIII/Vaccine Request | E22: EMAIL | F22: JTF North | G22: White Cell - Medical (MAJ Benton) | H22: J33 Message Center | I22: TF MED of JTF North requests Routine Adult Immunizations as follows: Hep A: 75 doses, Hep B: 90 doses, Hep A/B: 25 doses, TDAP: 15 doses, & H1N1: 435 doses. Note: TF MED has all expendable CL VIII to administer vaccines with the exception of needles (25g x 1"). Need items above NLT 0900 in preparation for incoming support personnel. | L22: JTF N to Coordinate with JFHQAL MED to set up CL VIII mission with MED DET. | P22: BENTON
A23: FS-16 | B23: 40302 | C23: 042100MAY10 | D23: MVA Medical Update 1 | E23: EMAIL | F23: JTF North | G23: White Cell - Medical (MAJ Benton) | H23: J33 Message Center | I23: UPDATE: Three (3) of the military personnel injurred received minor injuries from the accident and were treated/released at 2030. One (1) soldier received a minor head injury that requires him to remain overnight and further testing. | L23: Coordinate J1 Actions (LODs & Accountablity), Chaplain Support and Medical Patient Tracking. | P23: BENTON
A24: FS-17 | B24: 40303 | C24: 050859MAY10 | D24: Medical Equipment Repair | E24: EMAIL | F24: JTF South | G24: White Cell - Medical (MAJ Benton) | H24: J33 Message Center | I24: The TF MED (JTF S) is reporting that the dental xray machine in the Ft. Whiting medical facility is down and requesting medical maintenance support. | L24: JFHQ MED will set up support. Military support will not be available. Contract support will need to be coordinated. | P24: BENTON
A25: FS-18 | B25: 40303 | C25: 050859MAY10 | D25: MVA Medical Update 2 | E25: EMAIL | F25: JTF North | G25: White Cell - Medical (MAJ Benton) | H25: J33 Message Center | I25: UPDATE: SGT Joe Doe's condition has worsened and the SM will remain in the hospital until further notice. The Doe family is currently at Jackson Hospital and terribly upset with the fact that no military family support is being offered at this time. | L25: JFHQ MED will provide detailed patient tracking. J1 will account for SM in PERSTAT & Chaplian will send rep to meet with family. | P25: BENTON
A26: FS-19 | B26: 40304 | C26: 060700MAY10 | D26: Sexual Assault Incident | E26: EMAIL | F26: JTF South | G26: White Cell - Medical (MAJ Benton) | H26: JTF S Whitecell | I26: A SM from JTF South was brought to sick call this morning by her battle buddy. The SM was badly beaten and raped around 0200 by a fellow soldier. TF MED (JTF S) has stabilized the soldier's injuries and conducted the initial mental health evaluation. TF MED (JTF S) is requesting SM being transferred back to HOR (Birmingham) by MEDEVAC to complete follow up medical care. SM SSN: ###-###-1234 | L26: Should initiate J3 AVN coord, J1 SARC, Safety, MED, JAG, PAO and CID/CIV Police OPEN | P26: BENTON

Sheet Backup
A1: Hurricane Scenario
A2: Master Scenario Events List (MSEL)
A3: MSEL NUMBER | B3: DATE | C3: INJECT DTG | D3: SUBJECT | E3: INJECT MODE | F3: SEND FROM (Simulated) | G3: INJECTED BY | H3: SEND TO | I3: STORYLINE/THREAD | J3: ESF | K3: DESCRIPTION | L3: EXPECTED ACTION | M3: NOTES/REMARKS | N3: IMPLEMENTER (Actual Narrative) | O3: BACKGROUND INFORMATION | P3: Inject Author

Sheet Examples
A1: MSEL NUMBER | B1: DATE | C1: Time | D1: INJECT DTG | E1: SUBJECT | F1: INJECT MODE | G1: SEND FROM (Simulated) | H1: INJECTED BY | I1: SEND TO | J1: STORYLINE/THREAD | K1: ESF | L1: DESCRIPTION | M1: EXPECTED ACTION | N1: NOTES/REMARKS | O1: IMPLEMENTER (Actual Narrative) | P1: BACKGROUND INFORMATION | Q1: Inject Author
C2: 0.33333333 | D2: 1/0/2020 08:00:00 | K2: 5 | M2: A joint basis with (State Coordinating Officer), Federal Emergency Management Agency (FEMA) (Region #), FEMA Regional Response Coordination Center (RRCC) and (Appropriate Military Command) (via the [Defense Coordinating Office]). Crisis action planning will focus on vulnerabilities and resource availability. Crisis action planning will result in a (State Coordinating Officer)/FEMA (Region #) Planning Order. Begin incident-specific operational planning. | Q2: Example - Keane
C3: 0.33333333 | D3: 1/0/2020 08:00:00 | F3: Handout | G3: Control | I3: All | K3: 5 | O3: Scenario read-in, IAP and SitRep received. | Q3: Example - Keane
C4: 0.33333333 | D4: 1/0/2020 08:00:00 | F4: Handout | G4: Control | I4: All | K4: 5 | O4: Start of Exercise: (Operations Plan [OPLAN]) Phase 2 Operations begin at scenario: Landfall + (#) hours. | Q4: Example - Keane
C5: 0.33333333 | D5: 1/0/2020 08:00:00 | F5: Handout | G5: Control | I5: All | K5: 5, 15 | O5: Weather Package #4: (Month/Year) AM: warnings dropped (provided at Start of Exercise (Month/Day): summary (actual onset, etc.) and weather package "5 clear"). | Q5: Example - Keane
C6: 0.33333333 | D6: 1/0/2020 08:00:00 | F6: Handout | G6: Control | I6: All | K6: 5, 15 | O6: Weather Product: Weather summary/situation for exercise time period of landfall through (Month/Day) (NOT a package: "fill in gaps" product) Note slowing of storm, locational details, etc. Rest of Exercise weather is "real" (National Weather Service [NWS]) packages. | Q6: Example - Keane
C7: 0.33333333 | D7: 1/0/2020 08:00:00 | K7: 5 | O7: Activate (Emergency Management Assistance Compact [ EMAC])and applicable Memorandums of Understanding [MOUs]/(Memorandum of Agreement [MOAs]). - Coordinate mass care and temporary housing support to an estimated population of (#), including special needs and pets. - Coordinate evacuation operations (including prioritization). - Account for, shelter, and initiate evacuations of tourist populations. - Assess functionality of water distribution systems, and establish emergency water distribution. - Provide fuel at critical locations, plan for restoration of retail fuel delivery process. - Clear key transportation routes of debris. - Coordinate deployment of critical resources. - Deconflict power restoration priorities. | Q7: Example - Keane
C8: 0.33333333 | D8: 1/0/2020 08:00:00 | F8: Phone | G8: SimCell (City/County) | I8: ESF 8 | K8: 8 | M8: DoD Inject 135: See (Name) for details and additional information. | O8: Locals are requesting assistance with mortuary affairs. | Q8: Example - Keane
C9: 0.33680556 | D9: 1/0/2020 08:05:00 | F9: Phone | G9: SimCell (City/County) | I9: ESF 9 | K9: 9 | M9: Est. victims = (#–#) people | O9: Search and Rescue support is needed at the following locations: - Tourists sheltered in (Location) (Hotel) above 3rd floor with partial collapse and debris blocking exits, some trapped in elevator. - (City Fire Department) requests (#) type I (Urban Search and Rescue [USAR]) teams for operations within (Location). - Update of Group Care for elderly residents in central (City): residents tried to shelter in place but home collapsed. Multiple injuries, and potential trapped victims. - Structure collapse on (campus), trapping over a hundred people sheltered there. - (Retirement Community) reports (#) senior residents are stranded on the upper floors of their facility and are unable to use the elevators (power outage) or stairs. | Q9: Example - Keane
C10: 0.33680556 | D10: 1/0/2020 08:05:00 | F10: Phone | G10: SimCell (City/County) | I10: ESF 3 | K10: 3 | O10: Oil trucks can’t get to refinery due to traffic-clogged roads. Need police to open route to fuel tanks at (Location) refineries and prioritize routes to distribution points. | Q10: Example - Keane
C11: 0.34027778 | D11: 1/0/2020 08:10:00 | F11: Fax | G11: SimCell (City/County) | I11: ESF 8 | K11: 8 | M11: Details on damage for each location found in fax to be injected later, and in truth binder. | O11: Hospital Update: We anticipate (#) hospitals were affected by the storm and assume at a minimum (#) hospitals lost (#) percent of their windows and (#) are on generator power. So far we have received damage reports from the following hospitals and urgent care clinics: (Names of Clinics and Hospitals). In addition, the following Urgent Care Centers were in the inundation and are closed: the (Names of Clinics and Hospitals). | Q11: Example - Keane
C12: 0.34027778 | D12: 1/0/2020 08:10:00 | F12: Phone | G12: SimCell (City/County) | I12: ESF 6 | K12: 6 | O12: Many shelters are running out of potable water and supplies. When will more supplies be coming in from the (Location)? There is a need for food, blankets, first aid supplies, and hygiene kits. | Q12: Example - Keane
C13: 0.34375 | D13: 1/0/2020 08:15:00 | K13: 5 | M13: DoD Inject 136: See (Name) for details and additional information. | O13: FEMA assigns this mission to DoD, drafts a (Mission Assignment [MA]) to assist with the strategic airlift of FEMA commodities, and sends it to the (Defense Coordinating Officer [DCO/E]) for validation. | Q13: Example - Keane
C14: 0.34375 | D14: 1/0/2020 08:15:00 | F14: Phone | G14: SimCell (City/County) | I14: ESF 13 | K14: 13 | O14: (Location) airfield reports crowd of hundreds of civilians seeking food and shelter at front gate. In addition, thousands of others are congregating outside of fire houses looking for medical aid, food, water and where to go find shelter. | Q14: Example - Keane
C15: 0.34722222 | D15: 1/0/2020 08:20:00 | F15: Phone | G15: SimCell (City) | I15: ESF 1 | K15: 1 | O15: (City) International Airport remains closed because of debris on the runways. Anticipate one runway (in conjunction with (AFB) will be operational under daylight (Visual Flight Rules [VFR]) by midday (Month/Day). | Q15: Example - Keane
C16: 0.34722222 | D16: 1/0/2020 08:20:00 | F16: Phone | G16: SimCell (Utilities) | I16: ESF 6 | K16: 6 | O16: (Electric Company) requests base camp space for (#) linemen arriving from (Location) and priority sheltering for family members. | Q16: Example - Keane
C17: 0.35069444 | D17: 1/0/2020 08:25:00 | F17: Phone | G17: SimCell (State Tourist Association Emergency Operations Center [EOC]) | I17: ESF (#) | K17: 7 | M17: Identify power teams to assess specific generator requirements. If (City) (Department of Emergency Management) is not playing, they should be simulated so this request can be delivered to the (City Emergency Operations Center). | O17: Initial assessment of tourist population reports (#) tourists in hotels on (Location) (#) percent of hotels are without emergency power for elevators. (#) tourists are special needs. Request generator support for elevators. | Q17: Example - Keane
C18: 0.35416667 | D18: 1/0/2020 08:30:00 | F18: Phone | G18: SimCell (City and County) | I18: ESF 1 | K18: 1 | O18: (City) Harbor: Pier (#) and (#) were inspected and are intact. Depth alongside Piers (#) and (#) concurs with charted depth. There are damages to (#) pier-side ramp systems and perimeter fencing. A large portable crane used for offloading of cargo has mechanical damage to its arm and is nonfunctional, but could be fixed with (#) hours of maintenance. | Q18: Example - Keane
C19: 0.35416667 | D19: 1/0/2020 08:30:00 | F19: Phone | G19: SimCell (County) | I19: ESF 1 | K19: 7 | M19: Provide a status on the (Location). | O19: This is (City/County/State Emergency Management Agency) . When can we expect the (Location) to be operational so that we can receive fuel and supplies? | Q19: Example - Keane
C20: 0.35763889 | D20: 1/0/2020 08:35:00 | F20: Phone | G20: SimCell (City and County) | I20: ESF 1 | K20: 1 | O20: (City) Harbor is generally clear from the approaches to: (Points). Depths are clear to charted depths. At the eastern end of (Point), there is a sheen in close proximity to a barge that is resting on a partially sunk (drydock). It is unclear if the source of the sheen is the barge, the drydock or something else. | Q20: Example - Keane
C21: 0.35763889 | D21: 1/0/2020 08:35:00 | F21: Phone | G21: SimCell (Private Sector) | I21: ESF 1 | K21: 1 | O21: (Company Name) barges and (State)Tug and Barge were generally successful in conducting storm evasion, but the following barges were damaged: (Location) (#-ton barge), (Location) (#-ton barge), (Location) (#-ton barge). | Q21: Example - Keane
C22: 0.36111111 | D22: 1/0/2020 08:40:00 | F22: Phone | G22: SimCell (City and County) | I22: ESF 1 | K22: 1 | O22: Sunken and floating debris make Pier (#) inaccessible, and the piers themselves are covered with debris. (#) (Location) Gantry Cranes are damaged and require inspection, repair, and testing. There are oil and HazMat releases in the vicinity of Piers (#) and (#). The area north of Piers (#) and (#) is impacted by spilled fuel. Southern portion of (Location) is covered by a large pond of wastewater. | Q22: Example - Keane
C23: 0.36111111 | D23: 1/0/2020 08:40:00 | F23: Phone | G23: SimCell (Utilities) | I23: ESF 12 | K23: 12 | O23: (#) power poles and (#) cherry pickers arrive at (Location). (Electric Company) requests assistance in getting supplies to (City). | Q23: Example - Keane
C24: 0.36458333 | D24: 1/0/2020 08:45:00 | F24: Phone | G24: SimCell (City/County) | I24: ESF 8 | K24: 8 | M24: DoD Inject 46: See (Name) for details and additional information. | O24: Medical personnel are needed to augment medical facilities in several locations across (Location). | Q24: Example - Keane
C25: 0.36458333 | D25: 1/0/2020 08:45:00 | F25: Phone | G25: SimCell (City/County) | I25: ESF 6 | K25: 6 | M25: Cross-check. | O25: The following shelters have reportedly been severely damaged. Search and rescue resources are required and transportation to move evacuees is needed. The number of injuries at these locations is unknown. The shelters affected include: (Names of Shelters). | Q25: Example - Keane
C26: 0.36458333 | D26: 1/0/2020 08:45:00 | F26: Fax | G26: SimCell (City/County) | I26: ESF 1 | K26: 1 | O26: Port Update: - (City) Fire Department reports that the building located on Pier (#) that provides accommodations and a headquarters for the fire boat crew has collapsed. - Pier (#) has been completely blocked by floating debris. A (#)-ft. access roadway that extends across the inner slip has been washed out. - Several piers along (Location) have suffered severe structural damage. Fishing vessels, equipment, and supplies have been lost or damaged. Structures on the wharf to include the former cannery and the (Name) Restaurant have been inundated with flood waters. - Parking lot areas at the foot of (Name) Streets have been consumed by debris and vessels washed up on shore blocking inland access to Pier (#). - On the East Side of (Location) Drainage Canal, below (highway) Bridge, Pier (#) has been completely washed out. - At Pier (#) a transit shed used for storage and automobile parking has been washed out scattering equipment and supplies across the piers and leaving abandoned vehicles blocking portions of Pier (#). | Q26: Example - Keane
C27: 0.36805556 | D27: 1/0/2020 08:50:00 | F27: Fax | G27: Control | I27: All | K27: 5, 15 | M27: Situation report (SitRep)-type document outlining status of response efforts, shelter status, fire/ems/search and rescue, transportation, debris clearance status, health/medical, HazMat, utility updates. | O27: County perdisreps (Periodic Situation Reports) provided. | Q27: Example - Keane
C28: 0.36805556 | D28: 1/0/2020 08:50:00 | F28: Fax | G28: Control | I28: All | K28: 5, 15 | M28: SitRep-type document outlining status of response efforts, shelter status, fire/ems/search and rescue, transportation, debris clearance status, health/medical, HazMat, utility updates. | O28: County perdisreps (Periodic Situation Reports) provided. | Q28: Example - Keane
C29: 0.37152778 | D29: 1/0/2020 08:55:00 | F29: Phone | G29: SimCell (Hospitals) | I29: ESF 8 | K29: 8 | O29: Hospital Update: Generator fuel is running low in most medical facilities. Satellite phone batteries are wearing down and medical supplies are running low in ALL hospitals. The four (Hospital) medical equipment cached (Location) has been damaged and cannot be relied on; incomplete inventory makes gap analysis difficult. Need basic first aid supplies, as well as intravenous fluids, emergency room supplies, general hospital supplies. Expect supplies of most materials will run out in approximately (#) hours. | Q29: Example - Keane
C30: 0.375 | D30: 1/0/2020 09:00:00 | F30: Phone | G30: SimCell (City/County) | I30: ESF12 | K30: 7 | M30: DoD Inject 51: See (Name) for details and additional information. | O30: Locals are requesting fuel delivery in order to main essential services. | Q30: Example - Keane
C31: 0.375 | D31: 1/0/2020 09:00:00 | F31: Phone | G31: SimCell (City/County) | I31: ESF 12 | K31: 12 | M31: DoD Inject 53: This should be injected during phone call between the locals and JFO. See (Name) for details and additional information. | O31: Due to the power outage on (Location), emergency power is needed to maintain emergency water distribution to shelters and key facilities. | Q31: Example - Keane
C32: 0.375 | D32: 1/0/2020 09:00:00 | F32: Phone | G32: SimCell (County) | I32: ESF 1 | K32: 1 | M32: DoD Inject 54: See (Name) for details and additional information. | O32: Locals request emergency salvage operations for a grounded ship blocking the (Port) (City). | Q32: Example - Keane
C33: 0.375 | D33: 1/0/2020 09:00:00 | F33: Phone | G33: SimCell (City/County) | I33: ESF 3 | K33: 1, 3 | M33: DoD Inject 55: See (Name) for details and additional information. | O33: Locals request support for debris clearance on impassable highways. | Q33: Example - Keane
C34: 0.375 | D34: 1/0/2020 09:00:00 | F34: Phone | G34: SimCell (City/County) | I34: ESF 8 | K34: 8 | M34: DoD Inject 56: See (Name) for details and additional information. | O34: Request for a medical aid station to deploy to (Location). Request support to provide immediate care and first aid to windward residents for at least (#) month. | Q34: Example - Keane
C35: 0.375 | D35: 1/0/2020 09:00:00 | K35: 5 | O35: Conference with (City/County/State Emergency Management Agencies). | Q35: Example - Keane
C36: 0.375 | D36: 1/0/2020 09:00:00 | I36: ESF 8 | K36: 8 | M36: Details on damage for each location found in fax to be injected later and in truth binder. | O36: Hospital Update: Additional reports from hospitals on the (Locations) have been received. The following locations have provided reports of damage to their facilities: (Names of Locations). | Q36: Example - Keane
C37: 0.375 | D37: 1/0/2020 09:00:00 | K37: 5 | O37: (Unified Command Group [UCG]) requests plan for the postlandfall evacuation of tourists brief: the location of assembly areas, movement to ports of embarkation, and throughput estimates for the next (#) days. Include list of damaged hotels that are closed. Plans to schedule briefing. | Q37: Example - Keane
C38: 0.375 | D38: 1/0/2020 09:00:00 | F38: Phone | G38: SimCell (Governor's Office) | I38: ESF 15 | K38: 15 | M38: Provide information or a time when it will be provided. | O38: This is (Name), the executive assistant to the Lieutenant Governor. Governor (Name) would like to know the current steps being taken to mitigate and ensure the safety of the tourists in the (Locations). | Q38: Example - Keane
C39: 0.375 | D39: 1/0/2020 09:00:00 | G39: SimCell (City and County) | K39: 5 | M39: DoD Inject 138: See (Name) for details and additional information. | O39: A medium-lift rotary wing asset is needed to be on standby for personnel transport. FEMA assigns this mission to DoD, drafts an MA to provide a medium-lift rotary wing asset to be on standby for personnel transport, and sends it to the (District Corps of Engineers) for validation. | Q39: Example - Keane
C40: 0.375 | D40: 1/0/2020 09:00:00 | F40: Phone | G40: SimCell (City/County) | I40: ESF 10 | K40: 10 | O40: (Company Name) reports that a major pipeline that carries Jet Fuel-A from Pier (#) storage tanks on the opposite side of (Location) basin west of (Name) Road has suffered damage. Based on visual evidence and smell, there is a large area of contaminated soil that will need to be remediated. | Q40: Example - Keane
...

Sheet PRINT_SMALL
A1: MSEL # | B1: STATUS | C1: DTG | D1: SUBJECT | E1: INJECT MODE: / SEND FROM: / INJECTED BY: / SEND TO: | F1: STORYLINE / DESCRIPTION / NOTES & REMARKS / BACKGROUND INFO | G1: IMPLEMENTER | H1: EXPECTED ACTIONS | I1: AUTHOR
A2: ='Excercise - Al '!A2 -> 1 | B2: Ready to Inject | C2: ='Excercise - Al '!E2 -> 40298.208 | D2: =IF('Excercise - Al '!F2<>0,'Excercise - Al '!F2,"") -> 31st CHEM BDE - Notifies select staff | E2: =IF('Excercise - Al '!G2<>"","MODE: "&'Excercise - Al '!G2,"")&IF('Excercise - Al '!H2<>""," FROM: "&'Excercise - Al '!H2,"")&IF('Excercise - Al '!I2<>""," INJECTED BY: "&'Excercise - Al '!I2,"")&IF('Excercise - Al '!J2<>""," SEND TO: "&'Excercise - Al '!J2,"") -> MODE: Not Injected | F2: =IF('Excercise - Al '!K2<>"","STORYLINE: "&'Excercise - Al '!K2,"")&IF('Excercise - Al '!M2<>""," DESCRIPTION: "&'Excercise - Al '!M2,"")&IF('Excercise - Al '!O2<>""," NOTES/REMARKS: "&'Excercise - Al '!O2,"")&IF('Excercise - Al '!Q2<>""," BACKGROUND INFO: "&'Excercise - Al '!Q2,"") | G2: =IF('Excercise - Al '!P2<>"","IMPLEMENTER: "&'Excercise - Al '!P2,"") | H2: =IF('Excercise - Al '!N2<>"","EXPECTED ACTIONS: "&'Excercise - Al '!N2,"") | I2: ='Excercise - Al '!R2 -> Napier
